2025-09-07 21:49:16,539: Error running WSGI application
2025-09-07 21:49:16,560: ModuleNotFoundError: No module named 'psycopg2'
2025-09-07 21:49:16,560:   File "/var/www/buddyskincare_pythonanywhere_com_wsgi.py", line 22, in <module>
2025-09-07 21:49:16,560:     application = get_wsgi_application()
2025-09-07 21:49:16,560: 
2025-09-07 21:49:16,560:   File "/home/buddyskincare/.virtualenvs/venv/lib/python3.13/site-packages/django/core/wsgi.py", line 12, in get_wsgi_application
2025-09-07 21:49:16,560:     django.setup(set_prefix=False)
2025-09-07 21:49:16,561:     ~~~~~~~~~~~~^^^^^^^^^^^^^^^^^^
2025-09-07 21:49:16,561: 
2025-09-07 21:49:16,561:   File "/home/buddyskincare/.virtualenvs/venv/lib/python3.13/site-packages/django/__init__.py", line 24, in setup
2025-09-07 21:49:16,561:     apps.populate(settings.INSTALLED_APPS)
2025-09-07 21:49:16,561:     ~~~~~~~~~~~~~^^^^^^^^^^^^^^^^^^^^^^^^^
2025-09-07 21:49:16,561: 
2025-09-07 21:49:16,561:   File "/home/buddyskincare/.virtualenvs/venv/lib/python3.13/site-packages/django/apps/registry.py", line 116, in populate
2025-09-07 21:49:16,562:     app_config.import_models()
2025-09-07 21:49:16,562:     ~~~~~~~~~~~~~~~~~~~~~~~~^^
2025-09-07 21:49:16,562: 
2025-09-07 21:49:16,562:   File "/home/buddyskincare/.virtualenvs/venv/lib/python3.13/site-packages/django/apps/config.py", line 269, in import_models
2025-09-07 21:49:16,562:     self.models_module = import_module(models_module_name)
2025-09-07 21:49:16,562:                          ~~~~~~~~~~~~~^^^^^^^^^^^^^^^^^^^^
2025-09-07 21:49:16,562: 
2025-09-07 21:49:16,562:   File "/home/buddyskincare/BuddySkincare/BuddyApp/models.py", line 9, in <module>
2025-09-07 21:49:16,563:     from django.contrib.postgres.fields import JSONField as PostgresJSONField
2025-09-07 21:49:16,563: 
2025-09-07 21:49:16,563:   File "/home/buddyskincare/.virtualenvs/venv/lib/python3.13/site-packages/django/contrib/postgres/fields/__init__.py", line 1, in <module>
2025-09-07 21:49:16,563:     from .array import *  # NOQA
2025-09-07 21:49:16,563:     ^^^^^^^^^^^^^^^^^^^^
2025-09-07 21:49:16,563: 
2025-09-07 21:49:16,563:   File "/home/buddyskincare/.virtualenvs/venv/lib/python3.13/site-packages/django/contrib/postgres/fields/array.py", line 4, in <module>
2025-09-07 21:49:16,564:     from django.contrib.postgres.forms import SimpleArrayField
2025-09-07 21:49:16,564: 
2025-09-07 21:49:16,564:   File "/home/buddyskincare/.virtualenvs/venv/lib/python3.13/site-packages/django/contrib/postgres/forms/__init__.py", line 3, in <module>
2025-09-07 21:49:16,564:     from .ranges import *  # NOQA
2025-09-07 21:49:16,564:     ^^^^^^^^^^^^^^^^^^^^^
2025-09-07 21:49:16,564: 
2025-09-07 21:49:16,565:   File "/home/buddyskincare/.virtualenvs/venv/lib/python3.13/site-packages/django/contrib/postgres/forms/ranges.py", line 3, in <module>
2025-09-07 21:49:16,565:     from django.db.backends.postgresql.psycopg_any import (
2025-09-07 21:49:16,565:     ...<3 lines>...
2025-09-07 21:49:16,565:     )
2025-09-07 21:49:16,565: 
2025-09-07 21:49:16,565:   File "/home/buddyskincare/.virtualenvs/venv/lib/python3.13/site-packages/django/db/backends/postgresql/psycopg_any.py", line 77, in <module>
2025-09-07 21:49:16,566:     from psycopg2 import errors, extensions, sql  # NOQA
2025-09-07 21:49:16,566:     ^^^^^^^^^^^^^^^^^^^^^^^^^^^^^^^^^^^^^^^^^^^^
2025-09-07 21:49:16,566: ***************************************************
2025-09-07 21:49:16,566: If you're seeing an import error and don't know why,
2025-09-07 21:49:16,567: we have a dedicated help page to help you debug: 
2025-09-07 21:49:16,567: https://help.pythonanywhere.com/pages/DebuggingImportError/
2025-09-07 21:49:16,567: ***************************************************
2025-09-07 21:49:49,429: Error running WSGI application
2025-09-07 21:49:49,435: ModuleNotFoundError: No module named 'psycopg2'
2025-09-07 21:49:49,435:   File "/var/www/buddyskincare_pythonanywhere_com_wsgi.py", line 22, in <module>
2025-09-07 21:49:49,435:     application = get_wsgi_application()
2025-09-07 21:49:49,436: 
2025-09-07 21:49:49,436:   File "/home/buddyskincare/.virtualenvs/venv/lib/python3.13/site-packages/django/core/wsgi.py", line 12, in get_wsgi_application
2025-09-07 21:49:49,436:     django.setup(set_prefix=False)
2025-09-07 21:49:49,436:     ~~~~~~~~~~~~^^^^^^^^^^^^^^^^^^
2025-09-07 21:49:49,436: 
2025-09-07 21:49:49,436:   File "/home/buddyskincare/.virtualenvs/venv/lib/python3.13/site-packages/django/__init__.py", line 24, in setup
2025-09-07 21:49:49,437: 
2025-09-07 21:49:49,437:     app_config.import_models()
2025-09-07 21:49:49,438:     ~~~~~~~~~~~~~~~~~~~~~~~~^^
2025-09-07 21:49:49,438: 
2025-09-07 21:49:49,438:   File "/home/buddyskincare/.virtualenvs/venv/lib/python3.13/site-packages/django/apps/config.py", line 269, in import_models
2025-09-07 21:49:49,438:     self.models_module = import_module(models_module_name)
2025-09-07 21:49:49,438:                          ~~~~~~~~~~~~~^^^^^^^^^^^^^^^^^^^^
2025-09-07 21:49:49,438: 
2025-09-07 21:49:49,439:   File "/home/buddyskincare/BuddySkincare/BuddyApp/models.py", line 9, in <module>
2025-09-07 21:49:49,439:     from django.contrib.postgres.fields import JSONField as PostgresJSONField
2025-09-07 21:49:49,439: 
2025-09-07 21:49:49,439:   File "/home/buddyskincare/.virtualenvs/venv/lib/python3.13/site-packages/django/contrib/postgres/fields/__init__.py", line 1, in <module>
2025-09-07 21:49:49,439:     from .array import *  # NOQA
2025-09-07 21:49:49,439:     ^^^^^^^^^^^^^^^^^^^^
2025-09-07 21:49:49,440: 
2025-09-07 21:49:49,440:   File "/home/buddyskincare/.virtualenvs/venv/lib/python3.13/site-packages/django/contrib/postgres/fields/array.py", line 4, in <module>
2025-09-07 21:49:49,440:     from django.contrib.postgres.forms import SimpleArrayField
2025-09-07 21:49:49,440: 
2025-09-07 21:49:49,440:   File "/home/buddyskincare/.virtualenvs/venv/lib/python3.13/site-packages/django/contrib/postgres/forms/__init__.py", line 3, in <module>
2025-09-07 21:49:49,440:     from .ranges import *  # NOQA
2025-09-07 21:49:49,441:     ^^^^^^^^^^^^^^^^^^^^^
2025-09-07 21:49:49,441: 
2025-09-07 21:49:49,441:   File "/home/buddyskincare/.virtualenvs/venv/lib/python3.13/site-packages/django/contrib/postgres/forms/ranges.py", line 3, in <module>
2025-09-07 21:49:49,441:     from django.db.backends.postgresql.psycopg_any import (
2025-09-07 21:49:49,441:     ...<3 lines>...
2025-09-07 21:49:49,441:     )
2025-09-07 21:49:49,442: 
2025-09-07 21:49:49,442:   File "/home/buddyskincare/.virtualenvs/venv/lib/python3.13/site-packages/django/db/backends/postgresql/psycopg_any.py", line 77, in <module>
2025-09-07 21:49:49,442:     from psycopg2 import errors, extensions, sql  # NOQA
2025-09-07 21:49:49,442:     ^^^^^^^^^^^^^^^^^^^^^^^^^^^^^^^^^^^^^^^^^^^^
2025-09-07 21:49:49,442: ***************************************************
2025-09-07 21:49:49,442: If you're seeing an import error and don't know why,
2025-09-07 21:49:49,443: we have a dedicated help page to help you debug: 
2025-09-07 21:49:49,443: https://help.pythonanywhere.com/pages/DebuggingImportError/
2025-09-07 21:49:49,443: ***************************************************
2025-09-07 23:19:40,503: Error running WSGI application
2025-09-07 23:19:40,536:            ~~~~~~~~~~~~~~~~~~~~~~~~~~~~^^^^^^^^^^^^^^^^^^^^
2025-09-07 23:19:40,536: 
2025-09-07 23:19:40,536:   File "/home/buddyskincare/.virtualenvs/venv/lib/python3.13/site-packages/django/views/debug.py", line 69, in technical_500_response
2025-09-07 23:19:40,536:     html = reporter.get_traceback_html()
2025-09-07 23:19:40,537: 
2025-09-07 23:19:40,537:   File "/home/buddyskincare/.virtualenvs/venv/lib/python3.13/site-packages/django/views/debug.py", line 428, in get_traceback_html
2025-09-07 23:19:40,537:     c = Context(self.get_traceback_data(), use_l10n=False)
2025-09-07 23:19:40,537:                 ~~~~~~~~~~~~~~~~~~~~~~~^^
2025-09-07 23:19:40,537: 
2025-09-07 23:19:40,537:   File "/home/buddyskincare/.virtualenvs/venv/lib/python3.13/site-packages/django/views/debug.py", line 411, in get_traceback_data
2025-09-07 23:19:40,537:     c["raising_view_name"] = get_caller(self.request)
2025-09-07 23:19:40,538:                              ~~~~~~~~~~^^^^^^^^^^^^^^
2025-09-07 23:19:40,538: 
2025-09-07 23:19:40,538:   File "/home/buddyskincare/.virtualenvs/venv/lib/python3.13/site-packages/django/views/debug.py", line 102, in get_caller
2025-09-07 23:19:40,538:     resolver_match = resolve(request.path)
2025-09-07 23:19:40,538: 
2025-09-07 23:19:40,538:   File "/home/buddyskincare/.virtualenvs/venv/lib/python3.13/site-packages/django/urls/base.py", line 25, in resolve
2025-09-07 23:19:40,538:     return get_resolver(urlconf).resolve(path)
2025-09-07 23:19:40,539:            ~~~~~~~~~~~~~~~~~~~~~~~~~~~~~^^^^^^
2025-09-07 23:19:40,539: 
2025-09-07 23:19:40,539:   File "/home/buddyskincare/.virtualenvs/venv/lib/python3.13/site-packages/django/urls/resolvers.py", line 666, in resolve
2025-09-07 23:19:40,539:     for pattern in self.url_patterns:
2025-09-07 23:19:40,539:                    ^^^^^^^^^^^^^^^^^
2025-09-07 23:19:40,539: 
2025-09-07 23:19:40,539:   File "/home/buddyskincare/.virtualenvs/venv/lib/python3.13/site-packages/django/utils/functional.py", line 47, in __get__
2025-09-07 23:19:40,539:     res = instance.__dict__[self.name] = self.func(instance)
2025-09-07 23:19:40,540:                                          ~~~~~~~~~^^^^^^^^^^
2025-09-07 23:19:40,540: 
2025-09-07 23:19:40,540:   File "/home/buddyskincare/.virtualenvs/venv/lib/python3.13/site-packages/django/urls/resolvers.py", line 718, in url_patterns
2025-09-07 23:19:40,540:     patterns = getattr(self.urlconf_module, "urlpatterns", self.urlconf_module)
2025-09-07 23:19:40,540:                        ^^^^^^^^^^^^^^^^^^^
2025-09-07 23:19:40,541: 
2025-09-07 23:19:40,541:   File "/home/buddyskincare/.virtualenvs/venv/lib/python3.13/site-packages/django/utils/functional.py", line 47, in __get__
2025-09-07 23:19:40,541:     res = instance.__dict__[self.name] = self.func(instance)
2025-09-07 23:19:40,541:                                          ~~~~~~~~~^^^^^^^^^^
2025-09-07 23:19:40,541: 
2025-09-07 23:19:40,541:   File "/home/buddyskincare/.virtualenvs/venv/lib/python3.13/site-packages/django/urls/resolvers.py", line 711, in urlconf_module
2025-09-07 23:19:40,541:     return import_module(self.urlconf_name)
2025-09-07 23:19:40,541: 
2025-09-07 23:19:40,542:   File "/home/buddyskincare/BuddySkincare/BuddyProject/urls.py", line 32, in <module>
2025-09-07 23:19:40,542:     from BuddyApp.views import *
2025-09-07 23:19:40,542: 
2025-09-07 23:19:40,542:   File "/home/buddyskincare/BuddySkincare/BuddyApp/views.py", line 6, in <module>
2025-09-07 23:19:40,542:     from .serializers import *
2025-09-07 23:19:40,532:   File "/home/buddyskincare/BuddySkincare/BuddyApp/serializers.py", line 157
2025-09-07 23:19:40,533: 
2025-09-07 23:19:40,533:     // Check if there's already a voucher applied
2025-09-07 23:19:40,533: 
2025-09-07 23:19:40,533:                      ^
2025-09-07 23:19:40,533: 
2025-09-07 23:19:40,533: SyntaxError: unterminated string literal (detected at line 157)
2025-09-07 23:19:40,534:   File "/home/buddyskincare/.virtualenvs/venv/lib/python3.13/site-packages/django/core/handlers/wsgi.py", line 124, in __call__
2025-09-07 23:19:40,534:     response = self.get_response(request)
2025-09-07 23:19:40,534: 
2025-09-07 23:19:40,534:   File "/home/buddyskincare/.virtualenvs/venv/lib/python3.13/site-packages/django/core/handlers/base.py", line 140, in get_response
2025-09-07 23:19:40,534:     response = self._middleware_chain(request)
2025-09-07 23:19:40,534: 
2025-09-07 23:19:40,534:   File "/home/buddyskincare/.virtualenvs/venv/lib/python3.13/site-packages/django/core/handlers/exception.py", line 57, in inner
2025-09-07 23:19:40,535:     response = response_for_exception(request, exc)
2025-09-07 23:19:40,535: 
2025-09-07 23:19:40,535:   File "/home/buddyskincare/.virtualenvs/venv/lib/python3.13/site-packages/django/core/handlers/exception.py", line 141, in response_for_exception
2025-09-07 23:19:40,535:     response = handle_uncaught_exception(
2025-09-07 23:19:40,535:         request, get_resolver(get_urlconf()), sys.exc_info()
2025-09-07 23:19:40,535:     )
2025-09-07 23:19:40,536: 
2025-09-07 23:19:40,536:   File "/home/buddyskincare/.virtualenvs/venv/lib/python3.13/site-packages/django/core/handlers/exception.py", line 182, in handle_uncaught_exception
2025-09-07 23:19:40,536:     return debug.technical_500_response(request, *exc_info)
2025-09-07 23:19:57,239: Error running WSGI application
2025-09-07 23:19:57,251:   File "/home/buddyskincare/BuddySkincare/BuddyApp/serializers.py", line 157
2025-09-07 23:19:57,251: 
2025-09-07 23:19:57,251:     // Check if there's already a voucher applied
2025-09-07 23:19:57,251: 
2025-09-07 23:19:57,251:                      ^
2025-09-07 23:19:57,251: 
2025-09-07 23:19:57,251: SyntaxError: unterminated string literal (detected at line 157)
2025-09-07 23:19:57,252:   File "/home/buddyskincare/.virtualenvs/venv/lib/python3.13/site-packages/django/core/handlers/wsgi.py", line 124, in __call__
2025-09-07 23:19:57,252:     response = self.get_response(request)
2025-09-07 23:19:57,252: 
2025-09-07 23:19:57,252:   File "/home/buddyskincare/.virtualenvs/venv/lib/python3.13/site-packages/django/core/handlers/base.py", line 140, in get_response
2025-09-07 23:19:57,252:     response = self._middleware_chain(request)
2025-09-07 23:19:57,252: 
2025-09-07 23:19:57,252:   File "/home/buddyskincare/.virtualenvs/venv/lib/python3.13/site-packages/django/core/handlers/exception.py", line 57, in inner
2025-09-07 23:19:57,252:     response = response_for_exception(request, exc)
2025-09-07 23:19:57,252: 
2025-09-07 23:19:57,252:   File "/home/buddyskincare/.virtualenvs/venv/lib/python3.13/site-packages/django/core/handlers/exception.py", line 141, in response_for_exception
2025-09-07 23:19:57,252:     response = handle_uncaught_exception(
2025-09-07 23:19:57,253:         request, get_resolver(get_urlconf()), sys.exc_info()
2025-09-07 23:19:57,253:     )
2025-09-07 23:19:57,253: 
2025-09-07 23:19:57,253:   File "/home/buddyskincare/.virtualenvs/venv/lib/python3.13/site-packages/django/core/handlers/exception.py", line 182, in handle_uncaught_exception
2025-09-07 23:19:57,253:     return debug.technical_500_response(request, *exc_info)
2025-09-07 23:19:57,253:            ~~~~~~~~~~~~~~~~~~~~~~~~~~~~^^^^^^^^^^^^^^^^^^^^
2025-09-07 23:19:57,253: 
2025-09-07 23:19:57,253:   File "/home/buddyskincare/.virtualenvs/venv/lib/python3.13/site-packages/django/views/debug.py", line 69, in technical_500_response
2025-09-07 23:19:57,253:     html = reporter.get_traceback_html()
2025-09-07 23:19:57,253: 
2025-09-07 23:19:57,253:   File "/home/buddyskincare/.virtualenvs/venv/lib/python3.13/site-packages/django/views/debug.py", line 428, in get_traceback_html
2025-09-07 23:19:57,254:     c = Context(self.get_traceback_data(), use_l10n=False)
2025-09-07 23:19:57,254:     c["raising_view_name"] = get_caller(self.request)
2025-09-07 23:19:57,254:                              ~~~~~~~~~~^^^^^^^^^^^^^^
2025-09-07 23:19:57,254: 
2025-09-07 23:19:57,255:     resolver_match = resolve(request.path)
2025-09-07 23:19:57,255:   File "/home/buddyskincare/.virtualenvs/venv/lib/python3.13/site-packages/django/urls/base.py", line 25, in resolve
2025-09-07 23:19:57,255:     return get_resolver(urlconf).resolve(path)
2025-09-07 23:19:57,255: 
2025-09-07 23:19:57,256:     res = instance.__dict__[self.name] = self.func(instance)
2025-09-07 23:19:57,256:                                          ~~~~~~~~~^^^^^^^^^^
2025-09-07 23:19:57,256: 
2025-09-07 23:19:57,256:   File "/home/buddyskincare/.virtualenvs/venv/lib/python3.13/site-packages/django/urls/resolvers.py", line 718, in url_patterns
2025-09-07 23:19:57,256: 
2025-09-07 23:19:57,256:   File "/home/buddyskincare/.virtualenvs/venv/lib/python3.13/site-packages/django/utils/functional.py", line 47, in __get__
2025-09-07 23:19:57,256:     res = instance.__dict__[self.name] = self.func(instance)
2025-09-07 23:19:57,256:                                          ~~~~~~~~~^^^^^^^^^^
2025-09-07 23:19:57,256: 
2025-09-07 23:19:57,257:   File "/home/buddyskincare/.virtualenvs/venv/lib/python3.13/site-packages/django/urls/resolvers.py", line 711, in urlconf_module
2025-09-07 23:19:57,257:     return import_module(self.urlconf_name)
2025-09-07 23:19:57,257: 
2025-09-07 23:19:57,257:   File "/home/buddyskincare/BuddySkincare/BuddyProject/urls.py", line 32, in <module>
2025-09-07 23:19:57,257:     from BuddyApp.views import *
2025-09-07 23:19:57,257: 
2025-09-07 23:19:57,257:   File "/home/buddyskincare/BuddySkincare/BuddyApp/views.py", line 6, in <module>
2025-09-07 23:19:57,257:     from .serializers import *
2025-09-07 23:20:03,274: Error running WSGI application
2025-09-07 23:20:03,295:   File "/home/buddyskincare/BuddySkincare/BuddyApp/serializers.py", line 157
2025-09-07 23:20:03,295: 
2025-09-07 23:20:03,295:     // Check if there's already a voucher applied
2025-09-07 23:20:03,296: 
2025-09-07 23:20:03,296:                      ^
2025-09-07 23:20:03,296: 
2025-09-07 23:20:03,296: SyntaxError: unterminated string literal (detected at line 157)
2025-09-07 23:20:03,296:   File "/home/buddyskincare/.virtualenvs/venv/lib/python3.13/site-packages/django/core/handlers/wsgi.py", line 124, in __call__
2025-09-07 23:20:03,296:     response = self.get_response(request)
2025-09-07 23:20:03,297: 
2025-09-07 23:20:03,297:   File "/home/buddyskincare/.virtualenvs/venv/lib/python3.13/site-packages/django/core/handlers/base.py", line 140, in get_response
2025-09-07 23:20:03,297:     response = self._middleware_chain(request)
2025-09-07 23:20:03,297: 
2025-09-07 23:20:03,297:   File "/home/buddyskincare/.virtualenvs/venv/lib/python3.13/site-packages/django/core/handlers/exception.py", line 57, in inner
2025-09-07 23:20:03,297:     response = response_for_exception(request, exc)
2025-09-07 23:20:03,297: 
2025-09-07 23:20:03,297:   File "/home/buddyskincare/.virtualenvs/venv/lib/python3.13/site-packages/django/core/handlers/exception.py", line 141, in response_for_exception
2025-09-07 23:20:03,298:     response = handle_uncaught_exception(
2025-09-07 23:20:03,298:         request, get_resolver(get_urlconf()), sys.exc_info()
2025-09-07 23:20:03,298:     )
2025-09-07 23:20:03,298: 
2025-09-07 23:20:03,298:   File "/home/buddyskincare/.virtualenvs/venv/lib/python3.13/site-packages/django/core/handlers/exception.py", line 182, in handle_uncaught_exception
2025-09-07 23:20:03,298:     return debug.technical_500_response(request, *exc_info)
2025-09-07 23:20:03,298:            ~~~~~~~~~~~~~~~~~~~~~~~~~~~~^^^^^^^^^^^^^^^^^^^^
2025-09-07 23:20:03,299: 
2025-09-07 23:20:03,299:   File "/home/buddyskincare/.virtualenvs/venv/lib/python3.13/site-packages/django/views/debug.py", line 69, in technical_500_response
2025-09-07 23:20:03,299:     html = reporter.get_traceback_html()
2025-09-07 23:20:03,299: 
2025-09-07 23:20:03,299:   File "/home/buddyskincare/.virtualenvs/venv/lib/python3.13/site-packages/django/views/debug.py", line 428, in get_traceback_html
2025-09-07 23:20:03,299:     c = Context(self.get_traceback_data(), use_l10n=False)
2025-09-07 23:20:03,299:                 ~~~~~~~~~~~~~~~~~~~~~~~^^
2025-09-07 23:20:03,299: 
2025-09-07 23:20:03,300:   File "/home/buddyskincare/.virtualenvs/venv/lib/python3.13/site-packages/django/views/debug.py", line 411, in get_traceback_data
2025-09-07 23:20:03,300:     c["raising_view_name"] = get_caller(self.request)
2025-09-07 23:20:03,300:                              ~~~~~~~~~~^^^^^^^^^^^^^^
2025-09-07 23:20:03,300: 
2025-09-07 23:20:03,300:   File "/home/buddyskincare/.virtualenvs/venv/lib/python3.13/site-packages/django/views/debug.py", line 102, in get_caller
2025-09-07 23:20:03,300:     resolver_match = resolve(request.path)
2025-09-07 23:20:03,300: 
2025-09-07 23:20:03,300:   File "/home/buddyskincare/.virtualenvs/venv/lib/python3.13/site-packages/django/urls/base.py", line 25, in resolve
2025-09-07 23:20:03,301:     return get_resolver(urlconf).resolve(path)
2025-09-07 23:20:03,301:            ~~~~~~~~~~~~~~~~~~~~~~~~~~~~~^^^^^^
2025-09-07 23:20:03,301: 
2025-09-07 23:20:03,301:   File "/home/buddyskincare/.virtualenvs/venv/lib/python3.13/site-packages/django/urls/resolvers.py", line 666, in resolve
2025-09-07 23:20:03,301:     for pattern in self.url_patterns:
2025-09-07 23:20:03,301:                    ^^^^^^^^^^^^^^^^^
2025-09-07 23:20:03,301: 
2025-09-07 23:20:03,301:   File "/home/buddyskincare/.virtualenvs/venv/lib/python3.13/site-packages/django/utils/functional.py", line 47, in __get__
2025-09-07 23:20:03,302:     res = instance.__dict__[self.name] = self.func(instance)
2025-09-07 23:20:03,302:                                          ~~~~~~~~~^^^^^^^^^^
2025-09-07 23:20:03,302: 
2025-09-07 23:20:03,302:   File "/home/buddyskincare/.virtualenvs/venv/lib/python3.13/site-packages/django/urls/resolvers.py", line 718, in url_patterns
2025-09-07 23:20:03,302:     patterns = getattr(self.urlconf_module, "urlpatterns", self.urlconf_module)
2025-09-07 23:20:03,302:                        ^^^^^^^^^^^^^^^^^^^
2025-09-07 23:20:03,302: 
2025-09-07 23:20:03,302:   File "/home/buddyskincare/.virtualenvs/venv/lib/python3.13/site-packages/django/utils/functional.py", line 47, in __get__
2025-09-07 23:20:03,302:     res = instance.__dict__[self.name] = self.func(instance)
2025-09-07 23:20:03,302:                                          ~~~~~~~~~^^^^^^^^^^
2025-09-07 23:20:03,302: 
2025-09-07 23:20:03,302:   File "/home/buddyskincare/.virtualenvs/venv/lib/python3.13/site-packages/django/urls/resolvers.py", line 711, in urlconf_module
2025-09-07 23:20:03,303:     return import_module(self.urlconf_name)
2025-09-07 23:20:03,303: 
2025-09-07 23:20:03,303:   File "/home/buddyskincare/BuddySkincare/BuddyProject/urls.py", line 32, in <module>
2025-09-07 23:20:03,303:     from BuddyApp.views import *
2025-09-07 23:20:03,303: 
2025-09-07 23:20:03,303:   File "/home/buddyskincare/BuddySkincare/BuddyApp/views.py", line 6, in <module>
2025-09-07 23:20:03,303:     from .serializers import *
2025-09-07 23:20:15,719: Error running WSGI application
2025-09-07 23:20:15,730:   File "/home/buddyskincare/BuddySkincare/BuddyApp/serializers.py", line 157
2025-09-07 23:20:15,730: 
2025-09-07 23:20:15,730:     // Check if there's already a voucher applied
2025-09-07 23:20:15,731: 
2025-09-07 23:20:15,731:                      ^
2025-09-07 23:20:15,731: 
2025-09-07 23:20:15,731: SyntaxError: unterminated string literal (detected at line 157)
2025-09-07 23:20:15,731:   File "/home/buddyskincare/.virtualenvs/venv/lib/python3.13/site-packages/django/core/handlers/wsgi.py", line 124, in __call__
2025-09-07 23:20:15,731:     response = self.get_response(request)
2025-09-07 23:20:15,732: 
2025-09-07 23:20:15,732:   File "/home/buddyskincare/.virtualenvs/venv/lib/python3.13/site-packages/django/core/handlers/base.py", line 140, in get_response
2025-09-07 23:20:15,732:     response = self._middleware_chain(request)
2025-09-07 23:20:15,732: 
2025-09-07 23:20:15,732:   File "/home/buddyskincare/.virtualenvs/venv/lib/python3.13/site-packages/django/core/handlers/exception.py", line 57, in inner
2025-09-07 23:20:15,732:     response = response_for_exception(request, exc)
2025-09-07 23:20:15,732: 
2025-09-07 23:20:15,732:   File "/home/buddyskincare/.virtualenvs/venv/lib/python3.13/site-packages/django/core/handlers/exception.py", line 141, in response_for_exception
2025-09-07 23:20:15,732:     response = handle_uncaught_exception(
2025-09-07 23:20:15,732:         request, get_resolver(get_urlconf()), sys.exc_info()
2025-09-07 23:20:15,733:     )
2025-09-07 23:20:15,733: 
2025-09-07 23:20:15,733:   File "/home/buddyskincare/.virtualenvs/venv/lib/python3.13/site-packages/django/core/handlers/exception.py", line 182, in handle_uncaught_exception
2025-09-07 23:20:15,733:     return debug.technical_500_response(request, *exc_info)
2025-09-07 23:20:15,733:            ~~~~~~~~~~~~~~~~~~~~~~~~~~~~^^^^^^^^^^^^^^^^^^^^
2025-09-07 23:20:15,733: 
2025-09-07 23:20:15,733:   File "/home/buddyskincare/.virtualenvs/venv/lib/python3.13/site-packages/django/views/debug.py", line 69, in technical_500_response
2025-09-07 23:20:15,733:     html = reporter.get_traceback_html()
2025-09-07 23:20:15,733: 
2025-09-07 23:20:15,733:   File "/home/buddyskincare/.virtualenvs/venv/lib/python3.13/site-packages/django/views/debug.py", line 428, in get_traceback_html
2025-09-07 23:20:15,733:     c = Context(self.get_traceback_data(), use_l10n=False)
2025-09-07 23:20:15,733:                 ~~~~~~~~~~~~~~~~~~~~~~~^^
2025-09-07 23:20:15,734: 
2025-09-07 23:20:15,734:   File "/home/buddyskincare/.virtualenvs/venv/lib/python3.13/site-packages/django/views/debug.py", line 411, in get_traceback_data
2025-09-07 23:20:15,734:     c["raising_view_name"] = get_caller(self.request)
2025-09-07 23:20:15,734:                              ~~~~~~~~~~^^^^^^^^^^^^^^
2025-09-07 23:20:15,734: 
2025-09-07 23:20:15,734:   File "/home/buddyskincare/.virtualenvs/venv/lib/python3.13/site-packages/django/views/debug.py", line 102, in get_caller
2025-09-07 23:20:15,734:     resolver_match = resolve(request.path)
2025-09-07 23:20:15,734: 
2025-09-07 23:20:15,734:   File "/home/buddyskincare/.virtualenvs/venv/lib/python3.13/site-packages/django/urls/base.py", line 25, in resolve
2025-09-07 23:20:15,734:     return get_resolver(urlconf).resolve(path)
2025-09-07 23:20:15,735:            ~~~~~~~~~~~~~~~~~~~~~~~~~~~~~^^^^^^
2025-09-07 23:20:15,735: 
2025-09-07 23:20:15,735:   File "/home/buddyskincare/.virtualenvs/venv/lib/python3.13/site-packages/django/urls/resolvers.py", line 666, in resolve
2025-09-07 23:20:15,735:     for pattern in self.url_patterns:
2025-09-07 23:20:15,735:                    ^^^^^^^^^^^^^^^^^
2025-09-07 23:20:15,735: 
2025-09-07 23:20:15,735:   File "/home/buddyskincare/.virtualenvs/venv/lib/python3.13/site-packages/django/utils/functional.py", line 47, in __get__
2025-09-07 23:20:15,735:     res = instance.__dict__[self.name] = self.func(instance)
2025-09-07 23:20:15,735:                                          ~~~~~~~~~^^^^^^^^^^
2025-09-07 23:20:15,735: 
2025-09-07 23:20:15,735:   File "/home/buddyskincare/.virtualenvs/venv/lib/python3.13/site-packages/django/urls/resolvers.py", line 718, in url_patterns
2025-09-07 23:20:15,736:     patterns = getattr(self.urlconf_module, "urlpatterns", self.urlconf_module)
2025-09-07 23:20:15,736:                        ^^^^^^^^^^^^^^^^^^^
2025-09-07 23:20:15,736: 
2025-09-07 23:20:15,736:   File "/home/buddyskincare/.virtualenvs/venv/lib/python3.13/site-packages/django/utils/functional.py", line 47, in __get__
2025-09-07 23:20:15,736:     res = instance.__dict__[self.name] = self.func(instance)
2025-09-07 23:20:15,736:                                          ~~~~~~~~~^^^^^^^^^^
2025-09-07 23:20:15,736: 
2025-09-07 23:20:15,736:   File "/home/buddyskincare/.virtualenvs/venv/lib/python3.13/site-packages/django/urls/resolvers.py", line 711, in urlconf_module
2025-09-07 23:20:15,736:     return import_module(self.urlconf_name)
2025-09-07 23:20:15,736: 
2025-09-07 23:20:15,737:   File "/home/buddyskincare/BuddySkincare/BuddyProject/urls.py", line 32, in <module>
2025-09-07 23:20:15,737:     from BuddyApp.views import *
2025-09-07 23:20:15,737: 
2025-09-07 23:20:15,737:   File "/home/buddyskincare/BuddySkincare/BuddyApp/views.py", line 6, in <module>
2025-09-07 23:20:15,737:     from .serializers import *
2025-09-07 23:22:46,063:   File "/home/buddyskincare/BuddySkincare/BuddyApp/serializers.py", line 157
2025-09-07 23:22:46,064: 
2025-09-07 23:22:46,064:     // Check if there's already a voucher applied
2025-09-07 23:22:46,064: 
2025-09-07 23:22:46,064:                      ^
2025-09-07 23:22:46,064: 
2025-09-07 23:22:46,064: SyntaxError: unterminated string literal (detected at line 157)
2025-09-07 23:22:46,064:   File "/home/buddyskincare/.virtualenvs/venv/lib/python3.13/site-packages/django/core/handlers/wsgi.py", line 124, in __call__
2025-09-07 23:22:46,064:     response = self.get_response(request)
2025-09-07 23:22:46,064: 
2025-09-07 23:22:46,064:   File "/home/buddyskincare/.virtualenvs/venv/lib/python3.13/site-packages/django/core/handlers/base.py", line 140, in get_response
2025-09-07 23:22:46,065:     response = self._middleware_chain(request)
2025-09-07 23:22:46,065: 
2025-09-07 23:22:46,065:   File "/home/buddyskincare/.virtualenvs/venv/lib/python3.13/site-packages/django/core/handlers/exception.py", line 57, in inner
2025-09-07 23:22:46,065:     response = response_for_exception(request, exc)
2025-09-07 23:22:46,065: 
2025-09-07 23:22:46,065:   File "/home/buddyskincare/.virtualenvs/venv/lib/python3.13/site-packages/django/core/handlers/exception.py", line 141, in response_for_exception
2025-09-07 23:22:46,065:     response = handle_uncaught_exception(
2025-09-07 23:22:46,065:         request, get_resolver(get_urlconf()), sys.exc_info()
2025-09-07 23:22:46,065:     )
2025-09-07 23:22:46,065: 
2025-09-07 23:22:46,065:   File "/home/buddyskincare/.virtualenvs/venv/lib/python3.13/site-packages/django/core/handlers/exception.py", line 182, in handle_uncaught_exception
2025-09-07 23:22:46,066:     return debug.technical_500_response(request, *exc_info)
2025-09-07 23:22:46,066:            ~~~~~~~~~~~~~~~~~~~~~~~~~~~~^^^^^^^^^^^^^^^^^^^^
2025-09-07 23:22:46,066: 
2025-09-07 23:22:46,066:   File "/home/buddyskincare/.virtualenvs/venv/lib/python3.13/site-packages/django/views/debug.py", line 69, in technical_500_response
2025-09-07 23:22:46,066:     html = reporter.get_traceback_html()
2025-09-07 23:22:46,066: 
2025-09-07 23:22:46,066:   File "/home/buddyskincare/.virtualenvs/venv/lib/python3.13/site-packages/django/views/debug.py", line 428, in get_traceback_html
2025-09-07 23:22:46,066:     c = Context(self.get_traceback_data(), use_l10n=False)
2025-09-07 23:22:46,066:                 ~~~~~~~~~~~~~~~~~~~~~~~^^
2025-09-07 23:22:46,066: 
2025-09-07 23:22:46,066:   File "/home/buddyskincare/.virtualenvs/venv/lib/python3.13/site-packages/django/views/debug.py", line 411, in get_traceback_data
2025-09-07 23:22:46,066:     c["raising_view_name"] = get_caller(self.request)
2025-09-07 23:22:46,067:                              ~~~~~~~~~~^^^^^^^^^^^^^^
2025-09-07 23:22:46,067: 
2025-09-07 23:22:46,067:   File "/home/buddyskincare/.virtualenvs/venv/lib/python3.13/site-packages/django/views/debug.py", line 102, in get_caller
2025-09-07 23:22:46,067:     resolver_match = resolve(request.path)
2025-09-07 23:22:46,067: 
2025-09-07 23:22:46,067:   File "/home/buddyskincare/.virtualenvs/venv/lib/python3.13/site-packages/django/urls/base.py", line 25, in resolve
2025-09-07 23:22:46,067:     return get_resolver(urlconf).resolve(path)
2025-09-07 23:22:46,067:            ~~~~~~~~~~~~~~~~~~~~~~~~~~~~~^^^^^^
2025-09-07 23:22:46,067: 
2025-09-07 23:22:46,067:   File "/home/buddyskincare/.virtualenvs/venv/lib/python3.13/site-packages/django/urls/resolvers.py", line 666, in resolve
2025-09-07 23:22:46,067:     for pattern in self.url_patterns:
2025-09-07 23:22:46,067:                    ^^^^^^^^^^^^^^^^^
2025-09-07 23:22:46,068: 
2025-09-07 23:22:46,068:   File "/home/buddyskincare/.virtualenvs/venv/lib/python3.13/site-packages/django/utils/functional.py", line 47, in __get__
2025-09-07 23:22:46,068:     res = instance.__dict__[self.name] = self.func(instance)
2025-09-07 23:22:46,068:                                          ~~~~~~~~~^^^^^^^^^^
2025-09-07 23:22:46,068: 
2025-09-07 23:22:46,068:   File "/home/buddyskincare/.virtualenvs/venv/lib/python3.13/site-packages/django/urls/resolvers.py", line 718, in url_patterns
2025-09-07 23:22:46,068:     patterns = getattr(self.urlconf_module, "urlpatterns", self.urlconf_module)
2025-09-07 23:22:46,069:                        ^^^^^^^^^^^^^^^^^^^
2025-09-07 23:22:46,069: 
2025-09-07 23:22:46,069:   File "/home/buddyskincare/.virtualenvs/venv/lib/python3.13/site-packages/django/utils/functional.py", line 47, in __get__
2025-09-07 23:22:46,069:     res = instance.__dict__[self.name] = self.func(instance)
2025-09-07 23:22:46,069:                                          ~~~~~~~~~^^^^^^^^^^
2025-09-07 23:22:46,069: 
2025-09-07 23:22:46,069:   File "/home/buddyskincare/.virtualenvs/venv/lib/python3.13/site-packages/django/urls/resolvers.py", line 711, in urlconf_module
2025-09-07 23:22:46,070:     return import_module(self.urlconf_name)
2025-09-07 23:22:46,070: 
2025-09-07 23:22:46,070:   File "/home/buddyskincare/BuddySkincare/BuddyProject/urls.py", line 32, in <module>
2025-09-07 23:22:46,070:     from BuddyApp.views import *
2025-09-07 23:22:46,070: 
2025-09-07 23:22:46,070:   File "/home/buddyskincare/BuddySkincare/BuddyApp/views.py", line 6, in <module>
2025-09-07 23:22:46,070:     from .serializers import *
2025-09-07 23:22:46,053: Error running WSGI application
2025-09-07 23:25:00,527: Error running WSGI application
2025-09-07 23:25:00,573: 
2025-09-07 23:25:00,573:   File "/home/buddyskincare/.virtualenvs/venv/lib/python3.13/site-packages/django/urls/base.py", line 25, in resolve
2025-09-07 23:25:00,573:     return get_resolver(urlconf).resolve(path)
2025-09-07 23:25:00,573:            ~~~~~~~~~~~~~~~~~~~~~~~~~~~~~^^^^^^
2025-09-07 23:25:00,574: 
2025-09-07 23:25:00,574:   File "/home/buddyskincare/.virtualenvs/venv/lib/python3.13/site-packages/django/urls/resolvers.py", line 666, in resolve
2025-09-07 23:25:00,574:     for pattern in self.url_patterns:
2025-09-07 23:25:00,574:                    ^^^^^^^^^^^^^^^^^
2025-09-07 23:25:00,574: 
2025-09-07 23:25:00,574:   File "/home/buddyskincare/.virtualenvs/venv/lib/python3.13/site-packages/django/utils/functional.py", line 47, in __get__
2025-09-07 23:25:00,574:     res = instance.__dict__[self.name] = self.func(instance)
2025-09-07 23:25:00,575:                                          ~~~~~~~~~^^^^^^^^^^
2025-09-07 23:25:00,575: 
2025-09-07 23:25:00,575:   File "/home/buddyskincare/.virtualenvs/venv/lib/python3.13/site-packages/django/urls/resolvers.py", line 718, in url_patterns
2025-09-07 23:25:00,575:     patterns = getattr(self.urlconf_module, "urlpatterns", self.urlconf_module)
2025-09-07 23:25:00,575:                        ^^^^^^^^^^^^^^^^^^^
2025-09-07 23:25:00,575: 
2025-09-07 23:25:00,575:   File "/home/buddyskincare/.virtualenvs/venv/lib/python3.13/site-packages/django/utils/functional.py", line 47, in __get__
2025-09-07 23:25:00,576:     res = instance.__dict__[self.name] = self.func(instance)
2025-09-07 23:25:00,576:                                          ~~~~~~~~~^^^^^^^^^^
2025-09-07 23:25:00,576: 
2025-09-07 23:25:00,576:   File "/home/buddyskincare/.virtualenvs/venv/lib/python3.13/site-packages/django/urls/resolvers.py", line 711, in urlconf_module
2025-09-07 23:25:00,576:     return import_module(self.urlconf_name)
2025-09-07 23:25:00,576: 
2025-09-07 23:25:00,577:   File "/home/buddyskincare/BuddySkincare/BuddyProject/urls.py", line 32, in <module>
2025-09-07 23:25:00,577:     from BuddyApp.views import *
2025-09-07 23:25:00,577: 
2025-09-07 23:25:00,577:   File "/home/buddyskincare/BuddySkincare/BuddyApp/views.py", line 6, in <module>
2025-09-07 23:25:00,577:     from .serializers import *
2025-09-07 23:25:00,561:   File "/home/buddyskincare/BuddySkincare/BuddyApp/serializers.py", line 1
2025-09-07 23:25:00,561: 
2025-09-07 23:25:00,561:     // Main JavaScript for BuddySkincare Website
2025-09-07 23:25:00,562: 
2025-09-07 23:25:00,562:     ^^
2025-09-07 23:25:00,562: 
2025-09-07 23:25:00,562: SyntaxError: invalid syntax
2025-09-07 23:25:00,562:   File "/home/buddyskincare/.virtualenvs/venv/lib/python3.13/site-packages/django/core/handlers/wsgi.py", line 124, in __call__
2025-09-07 23:25:00,562:     response = self.get_response(request)
2025-09-07 23:25:00,563: 
2025-09-07 23:25:00,563:   File "/home/buddyskincare/.virtualenvs/venv/lib/python3.13/site-packages/django/core/handlers/base.py", line 140, in get_response
2025-09-07 23:25:00,563:     response = self._middleware_chain(request)
2025-09-07 23:25:00,563: 
2025-09-07 23:25:00,563:   File "/home/buddyskincare/.virtualenvs/venv/lib/python3.13/site-packages/django/core/handlers/exception.py", line 57, in inner
2025-09-07 23:25:00,563:     response = response_for_exception(request, exc)
2025-09-07 23:25:00,566: 
2025-09-07 23:25:00,568:   File "/home/buddyskincare/.virtualenvs/venv/lib/python3.13/site-packages/django/core/handlers/exception.py", line 141, in response_for_exception
2025-09-07 23:25:00,568:     response = handle_uncaught_exception(
2025-09-07 23:25:00,568:         request, get_resolver(get_urlconf()), sys.exc_info()
2025-09-07 23:25:00,569:     )
2025-09-07 23:25:00,569: 
2025-09-07 23:25:00,569:   File "/home/buddyskincare/.virtualenvs/venv/lib/python3.13/site-packages/django/core/handlers/exception.py", line 182, in handle_uncaught_exception
2025-09-07 23:25:00,569:     return debug.technical_500_response(request, *exc_info)
2025-09-07 23:25:00,569:            ~~~~~~~~~~~~~~~~~~~~~~~~~~~~^^^^^^^^^^^^^^^^^^^^
2025-09-07 23:25:00,569: 
2025-09-07 23:25:00,569:   File "/home/buddyskincare/.virtualenvs/venv/lib/python3.13/site-packages/django/views/debug.py", line 69, in technical_500_response
2025-09-07 23:25:00,571:     html = reporter.get_traceback_html()
2025-09-07 23:25:00,571: 
2025-09-07 23:25:00,572:   File "/home/buddyskincare/.virtualenvs/venv/lib/python3.13/site-packages/django/views/debug.py", line 428, in get_traceback_html
2025-09-07 23:25:00,572:     c = Context(self.get_traceback_data(), use_l10n=False)
2025-09-07 23:25:00,572:                 ~~~~~~~~~~~~~~~~~~~~~~~^^
2025-09-07 23:25:00,572: 
2025-09-07 23:25:00,572:   File "/home/buddyskincare/.virtualenvs/venv/lib/python3.13/site-packages/django/views/debug.py", line 411, in get_traceback_data
2025-09-07 23:25:00,572:     c["raising_view_name"] = get_caller(self.request)
2025-09-07 23:25:00,572:                              ~~~~~~~~~~^^^^^^^^^^^^^^
2025-09-07 23:25:00,573: 
2025-09-07 23:25:00,573:   File "/home/buddyskincare/.virtualenvs/venv/lib/python3.13/site-packages/django/views/debug.py", line 102, in get_caller
2025-09-07 23:25:00,573:     resolver_match = resolve(request.path)
2025-09-07 23:25:11,932: Error running WSGI application
2025-09-07 23:25:11,943:   File "/home/buddyskincare/BuddySkincare/BuddyApp/serializers.py", line 1
2025-09-07 23:25:11,943: 
2025-09-07 23:25:11,948:   File "/home/buddyskincare/.virtualenvs/venv/lib/python3.13/site-packages/django/urls/resolvers.py", line 666, in resolve
2025-09-07 23:25:11,948:     for pattern in self.url_patterns:
2025-09-07 23:25:11,948:                    ^^^^^^^^^^^^^^^^^
2025-09-07 23:25:11,948: 
2025-09-07 23:25:11,948:   File "/home/buddyskincare/.virtualenvs/venv/lib/python3.13/site-packages/django/utils/functional.py", line 47, in __get__
2025-09-07 23:25:11,948:     res = instance.__dict__[self.name] = self.func(instance)
2025-09-07 23:25:11,948:                                          ~~~~~~~~~^^^^^^^^^^
2025-09-07 23:25:11,948: 
2025-09-07 23:25:11,948:   File "/home/buddyskincare/.virtualenvs/venv/lib/python3.13/site-packages/django/urls/resolvers.py", line 718, in url_patterns
2025-09-07 23:25:11,948:     patterns = getattr(self.urlconf_module, "urlpatterns", self.urlconf_module)
2025-09-07 23:25:11,949:                        ^^^^^^^^^^^^^^^^^^^
2025-09-07 23:25:11,949: 
2025-09-07 23:25:11,949:   File "/home/buddyskincare/.virtualenvs/venv/lib/python3.13/site-packages/django/utils/functional.py", line 47, in __get__
2025-09-07 23:25:11,949:     res = instance.__dict__[self.name] = self.func(instance)
2025-09-07 23:25:11,949:                                          ~~~~~~~~~^^^^^^^^^^
2025-09-07 23:25:11,949: 
2025-09-07 23:25:11,949:   File "/home/buddyskincare/.virtualenvs/venv/lib/python3.13/site-packages/django/urls/resolvers.py", line 711, in urlconf_module
2025-09-07 23:25:11,949:     return import_module(self.urlconf_name)
2025-09-07 23:25:11,949: 
2025-09-07 23:25:11,949:   File "/home/buddyskincare/BuddySkincare/BuddyProject/urls.py", line 32, in <module>
2025-09-07 23:25:11,949:     from BuddyApp.views import *
2025-09-07 23:25:11,950: 
2025-09-07 23:25:11,950:   File "/home/buddyskincare/BuddySkincare/BuddyApp/views.py", line 6, in <module>
2025-09-07 23:25:11,950:     from .serializers import *
2025-09-07 23:25:17,160: Error running WSGI application
2025-09-07 23:25:17,171:   File "/home/buddyskincare/BuddySkincare/BuddyApp/serializers.py", line 1
2025-09-07 23:25:17,172: 
2025-09-07 23:25:17,172:     // Main JavaScript for BuddySkincare Website
2025-09-07 23:25:17,172: 
2025-09-07 23:25:17,172:     ^^
2025-09-07 23:25:17,172: 
2025-09-07 23:25:17,172: SyntaxError: invalid syntax
2025-09-07 23:25:17,172:   File "/home/buddyskincare/.virtualenvs/venv/lib/python3.13/site-packages/django/core/handlers/wsgi.py", line 124, in __call__
2025-09-07 23:25:17,173:     response = self.get_response(request)
2025-09-07 23:25:17,173: 
2025-09-07 23:25:17,173:   File "/home/buddyskincare/.virtualenvs/venv/lib/python3.13/site-packages/django/core/handlers/base.py", line 140, in get_response
2025-09-07 23:25:17,173:     response = self._middleware_chain(request)
2025-09-07 23:25:17,173: 
2025-09-07 23:25:17,173:   File "/home/buddyskincare/.virtualenvs/venv/lib/python3.13/site-packages/django/core/handlers/exception.py", line 57, in inner
2025-09-07 23:25:17,173:     response = response_for_exception(request, exc)
2025-09-07 23:25:17,173: 
2025-09-07 23:25:17,173:   File "/home/buddyskincare/.virtualenvs/venv/lib/python3.13/site-packages/django/core/handlers/exception.py", line 141, in response_for_exception
2025-09-07 23:25:17,173:     response = handle_uncaught_exception(
2025-09-07 23:25:17,174:         request, get_resolver(get_urlconf()), sys.exc_info()
2025-09-07 23:25:17,174:     )
2025-09-07 23:25:17,174: 
2025-09-07 23:25:17,174:   File "/home/buddyskincare/.virtualenvs/venv/lib/python3.13/site-packages/django/core/handlers/exception.py", line 182, in handle_uncaught_exception
2025-09-07 23:25:17,174:     return debug.technical_500_response(request, *exc_info)
2025-09-07 23:25:17,174:            ~~~~~~~~~~~~~~~~~~~~~~~~~~~~^^^^^^^^^^^^^^^^^^^^
2025-09-07 23:25:17,174: 
2025-09-07 23:25:17,174:   File "/home/buddyskincare/.virtualenvs/venv/lib/python3.13/site-packages/django/views/debug.py", line 69, in technical_500_response
2025-09-07 23:25:17,174:     html = reporter.get_traceback_html()
2025-09-07 23:25:17,174: 
2025-09-07 23:25:17,174:   File "/home/buddyskincare/.virtualenvs/venv/lib/python3.13/site-packages/django/views/debug.py", line 428, in get_traceback_html
2025-09-07 23:25:17,175:     c = Context(self.get_traceback_data(), use_l10n=False)
2025-09-07 23:25:17,175:                 ~~~~~~~~~~~~~~~~~~~~~~~^^
2025-09-07 23:25:17,175: 
2025-09-07 23:25:17,175:   File "/home/buddyskincare/.virtualenvs/venv/lib/python3.13/site-packages/django/views/debug.py", line 411, in get_traceback_data
2025-09-07 23:25:17,175:     c["raising_view_name"] = get_caller(self.request)
2025-09-07 23:25:17,175:                              ~~~~~~~~~~^^^^^^^^^^^^^^
2025-09-07 23:25:17,175: 
2025-09-07 23:25:17,175:   File "/home/buddyskincare/.virtualenvs/venv/lib/python3.13/site-packages/django/views/debug.py", line 102, in get_caller
2025-09-07 23:25:17,175:     resolver_match = resolve(request.path)
2025-09-07 23:25:17,176: 
2025-09-07 23:25:17,176:   File "/home/buddyskincare/.virtualenvs/venv/lib/python3.13/site-packages/django/urls/base.py", line 25, in resolve
2025-09-07 23:25:17,176:     return get_resolver(urlconf).resolve(path)
2025-09-07 23:25:17,176:            ~~~~~~~~~~~~~~~~~~~~~~~~~~~~~^^^^^^
2025-09-07 23:25:17,176: 
2025-09-07 23:25:17,176:   File "/home/buddyskincare/.virtualenvs/venv/lib/python3.13/site-packages/django/urls/resolvers.py", line 666, in resolve
2025-09-07 23:25:17,176:     for pattern in self.url_patterns:
2025-09-07 23:25:17,176:                    ^^^^^^^^^^^^^^^^^
2025-09-07 23:25:17,176: 
2025-09-07 23:25:17,176:   File "/home/buddyskincare/.virtualenvs/venv/lib/python3.13/site-packages/django/utils/functional.py", line 47, in __get__
2025-09-07 23:25:17,177:     res = instance.__dict__[self.name] = self.func(instance)
2025-09-07 23:25:17,177:                                          ~~~~~~~~~^^^^^^^^^^
2025-09-07 23:25:17,177: 
2025-09-07 23:25:17,177:   File "/home/buddyskincare/.virtualenvs/venv/lib/python3.13/site-packages/django/urls/resolvers.py", line 718, in url_patterns
2025-09-07 23:25:17,177:     patterns = getattr(self.urlconf_module, "urlpatterns", self.urlconf_module)
2025-09-07 23:25:17,177:                        ^^^^^^^^^^^^^^^^^^^
2025-09-07 23:25:17,177: 
2025-09-07 23:25:17,177:   File "/home/buddyskincare/.virtualenvs/venv/lib/python3.13/site-packages/django/utils/functional.py", line 47, in __get__
2025-09-07 23:25:17,177:     res = instance.__dict__[self.name] = self.func(instance)
2025-09-07 23:25:17,178:                                          ~~~~~~~~~^^^^^^^^^^
2025-09-07 23:25:17,178: 
2025-09-07 23:25:17,178:   File "/home/buddyskincare/.virtualenvs/venv/lib/python3.13/site-packages/django/urls/resolvers.py", line 711, in urlconf_module
2025-09-07 23:25:17,178:     return import_module(self.urlconf_name)
2025-09-07 23:25:17,178: 
2025-09-07 23:25:17,178:   File "/home/buddyskincare/BuddySkincare/BuddyProject/urls.py", line 32, in <module>
2025-09-07 23:25:17,178:     from BuddyApp.views import *
2025-09-07 23:25:17,178: 
2025-09-07 23:25:17,178:   File "/home/buddyskincare/BuddySkincare/BuddyApp/views.py", line 6, in <module>
2025-09-07 23:25:17,178:     from .serializers import *
2025-09-07 23:26:46,053: Error running WSGI application
2025-09-07 23:26:46,063:   File "/home/buddyskincare/BuddySkincare/BuddyApp/serializers.py", line 1
2025-09-07 23:26:46,064: 
2025-09-07 23:26:46,064:     // Main JavaScript for BuddySkincare Website
2025-09-07 23:26:46,064: 
2025-09-07 23:26:46,064:     ^^
2025-09-07 23:26:46,064: 
2025-09-07 23:26:46,064: SyntaxError: invalid syntax
2025-09-07 23:26:46,064:   File "/home/buddyskincare/.virtualenvs/venv/lib/python3.13/site-packages/django/core/handlers/wsgi.py", line 124, in __call__
2025-09-07 23:26:46,064:     response = self.get_response(request)
2025-09-07 23:26:46,064: 
2025-09-07 23:26:46,064:   File "/home/buddyskincare/.virtualenvs/venv/lib/python3.13/site-packages/django/core/handlers/base.py", line 140, in get_response
2025-09-07 23:26:46,065:     response = self._middleware_chain(request)
2025-09-07 23:26:46,065: 
2025-09-07 23:26:46,065:   File "/home/buddyskincare/.virtualenvs/venv/lib/python3.13/site-packages/django/core/handlers/exception.py", line 57, in inner
2025-09-07 23:26:46,065:     response = response_for_exception(request, exc)
2025-09-07 23:26:46,065: 
2025-09-07 23:26:46,065:   File "/home/buddyskincare/.virtualenvs/venv/lib/python3.13/site-packages/django/core/handlers/exception.py", line 141, in response_for_exception
2025-09-07 23:26:46,065:     response = handle_uncaught_exception(
2025-09-07 23:26:46,065:         request, get_resolver(get_urlconf()), sys.exc_info()
2025-09-07 23:26:46,066:     )
2025-09-07 23:26:46,066: 
2025-09-07 23:26:46,066:   File "/home/buddyskincare/.virtualenvs/venv/lib/python3.13/site-packages/django/core/handlers/exception.py", line 182, in handle_uncaught_exception
2025-09-07 23:26:46,066:     return debug.technical_500_response(request, *exc_info)
2025-09-07 23:26:46,066:            ~~~~~~~~~~~~~~~~~~~~~~~~~~~~^^^^^^^^^^^^^^^^^^^^
2025-09-07 23:26:46,066: 
2025-09-07 23:26:46,066:   File "/home/buddyskincare/.virtualenvs/venv/lib/python3.13/site-packages/django/views/debug.py", line 69, in technical_500_response
2025-09-07 23:26:46,066:     html = reporter.get_traceback_html()
2025-09-07 23:26:46,066: 
2025-09-07 23:26:46,067:   File "/home/buddyskincare/.virtualenvs/venv/lib/python3.13/site-packages/django/views/debug.py", line 428, in get_traceback_html
2025-09-07 23:26:46,067:     c = Context(self.get_traceback_data(), use_l10n=False)
2025-09-07 23:26:46,067:                 ~~~~~~~~~~~~~~~~~~~~~~~^^
2025-09-07 23:26:46,067: 
2025-09-07 23:26:46,067:   File "/home/buddyskincare/.virtualenvs/venv/lib/python3.13/site-packages/django/views/debug.py", line 411, in get_traceback_data
2025-09-07 23:26:46,067:     c["raising_view_name"] = get_caller(self.request)
2025-09-07 23:26:46,067:                              ~~~~~~~~~~^^^^^^^^^^^^^^
2025-09-07 23:26:46,067: 
2025-09-07 23:26:46,067:   File "/home/buddyskincare/.virtualenvs/venv/lib/python3.13/site-packages/django/views/debug.py", line 102, in get_caller
2025-09-07 23:26:46,067:     resolver_match = resolve(request.path)
2025-09-07 23:26:46,068: 
2025-09-07 23:26:46,068:   File "/home/buddyskincare/.virtualenvs/venv/lib/python3.13/site-packages/django/urls/base.py", line 25, in resolve
2025-09-07 23:26:46,068:     return get_resolver(urlconf).resolve(path)
2025-09-07 23:26:46,068:            ~~~~~~~~~~~~~~~~~~~~~~~~~~~~~^^^^^^
2025-09-07 23:26:46,068: 
2025-09-07 23:26:46,068:   File "/home/buddyskincare/.virtualenvs/venv/lib/python3.13/site-packages/django/urls/resolvers.py", line 666, in resolve
2025-09-07 23:26:46,068:     for pattern in self.url_patterns:
2025-09-07 23:26:46,068:                    ^^^^^^^^^^^^^^^^^
2025-09-07 23:26:46,068: 
2025-09-07 23:26:46,068:   File "/home/buddyskincare/.virtualenvs/venv/lib/python3.13/site-packages/django/utils/functional.py", line 47, in __get__
2025-09-07 23:26:46,068:     res = instance.__dict__[self.name] = self.func(instance)
2025-09-07 23:26:46,069:                                          ~~~~~~~~~^^^^^^^^^^
2025-09-07 23:26:46,069: 
2025-09-07 23:26:46,069:   File "/home/buddyskincare/.virtualenvs/venv/lib/python3.13/site-packages/django/urls/resolvers.py", line 718, in url_patterns
2025-09-07 23:26:46,069:     patterns = getattr(self.urlconf_module, "urlpatterns", self.urlconf_module)
2025-09-07 23:26:46,069:                        ^^^^^^^^^^^^^^^^^^^
2025-09-07 23:26:46,069: 
2025-09-07 23:26:46,069:   File "/home/buddyskincare/.virtualenvs/venv/lib/python3.13/site-packages/django/utils/functional.py", line 47, in __get__
2025-09-07 23:26:46,069:     res = instance.__dict__[self.name] = self.func(instance)
2025-09-07 23:26:46,069:                                          ~~~~~~~~~^^^^^^^^^^
2025-09-07 23:26:46,069: 
2025-09-07 23:26:46,069:   File "/home/buddyskincare/.virtualenvs/venv/lib/python3.13/site-packages/django/urls/resolvers.py", line 711, in urlconf_module
2025-09-07 23:26:46,070:     return import_module(self.urlconf_name)
2025-09-07 23:26:46,070: 
2025-09-07 23:26:46,070:   File "/home/buddyskincare/BuddySkincare/BuddyProject/urls.py", line 32, in <module>
2025-09-07 23:26:46,070:     from BuddyApp.views import *
2025-09-07 23:26:46,070: 
2025-09-07 23:26:46,070:   File "/home/buddyskincare/BuddySkincare/BuddyApp/views.py", line 6, in <module>
2025-09-07 23:26:46,070:     from .serializers import *
2025-09-07 23:28:52,836:   File "/home/buddyskincare/BuddySkincare/BuddyApp/serializers.py", line 410
2025-09-07 23:28:52,836: 
2025-09-07 23:28:52,836:     amount_vnd = (Decimal(str(o.total_amount or 0))
2025-09-07 23:28:52,836: 
2025-09-07 23:28:52,836:                  ^
2025-09-07 23:28:52,837: 
2025-09-07 23:28:52,837: SyntaxError: '(' was never closed
2025-09-07 23:28:52,837:   File "/home/buddyskincare/.virtualenvs/venv/lib/python3.13/site-packages/django/core/handlers/wsgi.py", line 124, in __call__
2025-09-07 23:28:52,837:     response = self.get_response(request)
2025-09-07 23:28:52,837: 
2025-09-07 23:28:52,837:   File "/home/buddyskincare/.virtualenvs/venv/lib/python3.13/site-packages/django/core/handlers/base.py", line 140, in get_response
2025-09-07 23:28:52,837:     response = self._middleware_chain(request)
2025-09-07 23:28:52,837: 
2025-09-07 23:28:52,837:   File "/home/buddyskincare/.virtualenvs/venv/lib/python3.13/site-packages/django/core/handlers/exception.py", line 57, in inner
2025-09-07 23:28:52,837:     response = response_for_exception(request, exc)
2025-09-07 23:28:52,837: 
2025-09-07 23:28:52,837:   File "/home/buddyskincare/.virtualenvs/venv/lib/python3.13/site-packages/django/core/handlers/exception.py", line 141, in response_for_exception
2025-09-07 23:28:52,837:     response = handle_uncaught_exception(
2025-09-07 23:28:52,838:         request, get_resolver(get_urlconf()), sys.exc_info()
2025-09-07 23:28:52,838:     )
2025-09-07 23:28:52,838: 
2025-09-07 23:28:52,838:   File "/home/buddyskincare/.virtualenvs/venv/lib/python3.13/site-packages/django/core/handlers/exception.py", line 182, in handle_uncaught_exception
2025-09-07 23:28:52,838:     return debug.technical_500_response(request, *exc_info)
2025-09-07 23:28:52,838:            ~~~~~~~~~~~~~~~~~~~~~~~~~~~~^^^^^^^^^^^^^^^^^^^^
2025-09-07 23:28:52,838: 
2025-09-07 23:28:52,838:   File "/home/buddyskincare/.virtualenvs/venv/lib/python3.13/site-packages/django/views/debug.py", line 69, in technical_500_response
2025-09-07 23:28:52,838:     html = reporter.get_traceback_html()
2025-09-07 23:28:52,838: 
2025-09-07 23:28:52,838:   File "/home/buddyskincare/.virtualenvs/venv/lib/python3.13/site-packages/django/views/debug.py", line 428, in get_traceback_html
2025-09-07 23:28:52,839:     c = Context(self.get_traceback_data(), use_l10n=False)
2025-09-07 23:28:52,839:                 ~~~~~~~~~~~~~~~~~~~~~~~^^
2025-09-07 23:28:52,839: 
2025-09-07 23:28:52,839:   File "/home/buddyskincare/.virtualenvs/venv/lib/python3.13/site-packages/django/views/debug.py", line 411, in get_traceback_data
2025-09-07 23:28:52,839:     c["raising_view_name"] = get_caller(self.request)
2025-09-07 23:28:52,839:                              ~~~~~~~~~~^^^^^^^^^^^^^^
2025-09-07 23:28:52,839: 
2025-09-07 23:28:52,839:   File "/home/buddyskincare/.virtualenvs/venv/lib/python3.13/site-packages/django/views/debug.py", line 102, in get_caller
2025-09-07 23:28:52,839:     resolver_match = resolve(request.path)
2025-09-07 23:28:52,839: 
2025-09-07 23:28:52,840:   File "/home/buddyskincare/.virtualenvs/venv/lib/python3.13/site-packages/django/urls/base.py", line 25, in resolve
2025-09-07 23:28:52,840:     return get_resolver(urlconf).resolve(path)
2025-09-07 23:28:52,840:            ~~~~~~~~~~~~~~~~~~~~~~~~~~~~~^^^^^^
2025-09-07 23:28:52,840: 
2025-09-07 23:28:52,840:   File "/home/buddyskincare/.virtualenvs/venv/lib/python3.13/site-packages/django/urls/resolvers.py", line 666, in resolve
2025-09-07 23:28:52,840:     for pattern in self.url_patterns:
2025-09-07 23:28:52,840:                    ^^^^^^^^^^^^^^^^^
2025-09-07 23:28:52,840: 
2025-09-07 23:28:52,840:   File "/home/buddyskincare/.virtualenvs/venv/lib/python3.13/site-packages/django/utils/functional.py", line 47, in __get__
2025-09-07 23:28:52,840:     res = instance.__dict__[self.name] = self.func(instance)
2025-09-07 23:28:52,840:                                          ~~~~~~~~~^^^^^^^^^^
2025-09-07 23:28:52,840: 
2025-09-07 23:28:52,840:   File "/home/buddyskincare/.virtualenvs/venv/lib/python3.13/site-packages/django/urls/resolvers.py", line 718, in url_patterns
2025-09-07 23:28:52,841:     patterns = getattr(self.urlconf_module, "urlpatterns", self.urlconf_module)
2025-09-07 23:28:52,841:                        ^^^^^^^^^^^^^^^^^^^
2025-09-07 23:28:52,841: 
2025-09-07 23:28:52,841:   File "/home/buddyskincare/.virtualenvs/venv/lib/python3.13/site-packages/django/utils/functional.py", line 47, in __get__
2025-09-07 23:28:52,841:     res = instance.__dict__[self.name] = self.func(instance)
2025-09-07 23:28:52,841:                                          ~~~~~~~~~^^^^^^^^^^
2025-09-07 23:28:52,841: 
2025-09-07 23:28:52,841:   File "/home/buddyskincare/.virtualenvs/venv/lib/python3.13/site-packages/django/urls/resolvers.py", line 711, in urlconf_module
2025-09-07 23:28:52,841:     return import_module(self.urlconf_name)
2025-09-07 23:28:52,841: 
2025-09-07 23:28:52,841:   File "/home/buddyskincare/BuddySkincare/BuddyProject/urls.py", line 32, in <module>
2025-09-07 23:28:52,841:     from BuddyApp.views import *
2025-09-07 23:28:52,842: 
2025-09-07 23:28:52,842:   File "/home/buddyskincare/BuddySkincare/BuddyApp/views.py", line 6, in <module>
2025-09-07 23:28:52,842:     from .serializers import *
2025-09-07 23:28:52,820: Error running WSGI application
2025-09-07 23:29:04,058: Error running WSGI application
2025-09-07 23:29:04,070:   File "/home/buddyskincare/BuddySkincare/BuddyApp/serializers.py", line 410
2025-09-07 23:29:04,070: 
2025-09-07 23:29:04,070:     amount_vnd = (Decimal(str(o.total_amount or 0))
2025-09-07 23:29:04,071: 
2025-09-07 23:29:04,071:                  ^
2025-09-07 23:29:04,071: 
2025-09-07 23:29:04,071: SyntaxError: '(' was never closed
2025-09-07 23:29:04,071:   File "/home/buddyskincare/.virtualenvs/venv/lib/python3.13/site-packages/django/core/handlers/wsgi.py", line 124, in __call__
2025-09-07 23:29:04,071:     response = self.get_response(request)
2025-09-07 23:29:04,071: 
2025-09-07 23:29:04,071:   File "/home/buddyskincare/.virtualenvs/venv/lib/python3.13/site-packages/django/core/handlers/base.py", line 140, in get_response
2025-09-07 23:29:04,071:     response = self._middleware_chain(request)
2025-09-07 23:29:04,072: 
2025-09-07 23:29:04,072:   File "/home/buddyskincare/.virtualenvs/venv/lib/python3.13/site-packages/django/core/handlers/exception.py", line 57, in inner
2025-09-07 23:29:04,072:     response = response_for_exception(request, exc)
2025-09-07 23:29:04,072: 
2025-09-07 23:29:04,072:   File "/home/buddyskincare/.virtualenvs/venv/lib/python3.13/site-packages/django/core/handlers/exception.py", line 141, in response_for_exception
2025-09-07 23:29:04,072:     response = handle_uncaught_exception(
2025-09-07 23:29:04,072:         request, get_resolver(get_urlconf()), sys.exc_info()
2025-09-07 23:29:04,072:     )
2025-09-07 23:29:04,072: 
2025-09-07 23:29:04,072:   File "/home/buddyskincare/.virtualenvs/venv/lib/python3.13/site-packages/django/core/handlers/exception.py", line 182, in handle_uncaught_exception
2025-09-07 23:29:04,072:     return debug.technical_500_response(request, *exc_info)
2025-09-07 23:29:04,073:            ~~~~~~~~~~~~~~~~~~~~~~~~~~~~^^^^^^^^^^^^^^^^^^^^
2025-09-07 23:29:04,073: 
2025-09-07 23:29:04,073:   File "/home/buddyskincare/.virtualenvs/venv/lib/python3.13/site-packages/django/views/debug.py", line 69, in technical_500_response
2025-09-07 23:29:04,073:     html = reporter.get_traceback_html()
2025-09-07 23:29:04,073: 
2025-09-07 23:29:04,073:   File "/home/buddyskincare/.virtualenvs/venv/lib/python3.13/site-packages/django/views/debug.py", line 428, in get_traceback_html
2025-09-07 23:29:04,073:     c = Context(self.get_traceback_data(), use_l10n=False)
2025-09-07 23:29:04,073:                 ~~~~~~~~~~~~~~~~~~~~~~~^^
2025-09-07 23:29:04,073: 
2025-09-07 23:29:04,073:   File "/home/buddyskincare/.virtualenvs/venv/lib/python3.13/site-packages/django/views/debug.py", line 411, in get_traceback_data
2025-09-07 23:29:04,073:     c["raising_view_name"] = get_caller(self.request)
2025-09-07 23:29:04,074:                              ~~~~~~~~~~^^^^^^^^^^^^^^
2025-09-07 23:29:04,074: 
2025-09-07 23:29:04,074:   File "/home/buddyskincare/.virtualenvs/venv/lib/python3.13/site-packages/django/views/debug.py", line 102, in get_caller
2025-09-07 23:29:04,074:     resolver_match = resolve(request.path)
2025-09-07 23:29:04,074: 
2025-09-07 23:29:04,074:   File "/home/buddyskincare/.virtualenvs/venv/lib/python3.13/site-packages/django/urls/base.py", line 25, in resolve
2025-09-07 23:29:04,074:     return get_resolver(urlconf).resolve(path)
2025-09-07 23:29:04,074:            ~~~~~~~~~~~~~~~~~~~~~~~~~~~~~^^^^^^
2025-09-07 23:29:04,074: 
2025-09-07 23:29:04,074:   File "/home/buddyskincare/.virtualenvs/venv/lib/python3.13/site-packages/django/urls/resolvers.py", line 666, in resolve
2025-09-07 23:29:04,074:     for pattern in self.url_patterns:
2025-09-07 23:29:04,075:                    ^^^^^^^^^^^^^^^^^
2025-09-07 23:29:04,075: 
2025-09-07 23:29:04,075:   File "/home/buddyskincare/.virtualenvs/venv/lib/python3.13/site-packages/django/utils/functional.py", line 47, in __get__
2025-09-07 23:29:04,075:     res = instance.__dict__[self.name] = self.func(instance)
2025-09-07 23:29:04,075:                                          ~~~~~~~~~^^^^^^^^^^
2025-09-07 23:29:04,075: 
2025-09-07 23:29:04,075:   File "/home/buddyskincare/.virtualenvs/venv/lib/python3.13/site-packages/django/urls/resolvers.py", line 718, in url_patterns
2025-09-07 23:29:04,075:     patterns = getattr(self.urlconf_module, "urlpatterns", self.urlconf_module)
2025-09-07 23:29:04,076:                        ^^^^^^^^^^^^^^^^^^^
2025-09-07 23:29:04,076: 
2025-09-07 23:29:04,076:   File "/home/buddyskincare/.virtualenvs/venv/lib/python3.13/site-packages/django/utils/functional.py", line 47, in __get__
2025-09-07 23:29:04,076:     res = instance.__dict__[self.name] = self.func(instance)
2025-09-07 23:29:04,076:                                          ~~~~~~~~~^^^^^^^^^^
2025-09-07 23:29:04,076: 
2025-09-07 23:29:04,076:   File "/home/buddyskincare/.virtualenvs/venv/lib/python3.13/site-packages/django/urls/resolvers.py", line 711, in urlconf_module
2025-09-07 23:29:04,076:     return import_module(self.urlconf_name)
2025-09-07 23:29:04,076: 
2025-09-07 23:29:04,076:   File "/home/buddyskincare/BuddySkincare/BuddyProject/urls.py", line 32, in <module>
2025-09-07 23:29:04,076:     from BuddyApp.views import *
2025-09-07 23:29:04,076: 
2025-09-07 23:29:04,077:   File "/home/buddyskincare/BuddySkincare/BuddyApp/views.py", line 6, in <module>
2025-09-07 23:29:04,077:     from .serializers import *
2025-09-07 23:29:10,538: Error running WSGI application
2025-09-07 23:29:10,556:   File "/home/buddyskincare/BuddySkincare/BuddyApp/serializers.py", line 410
2025-09-07 23:29:10,557: 
2025-09-07 23:29:10,557:     amount_vnd = (Decimal(str(o.total_amount or 0))
2025-09-07 23:29:10,557: 
2025-09-07 23:29:10,557:                  ^
2025-09-07 23:29:10,557: 
2025-09-07 23:29:10,558: SyntaxError: '(' was never closed
2025-09-07 23:29:10,558:   File "/home/buddyskincare/.virtualenvs/venv/lib/python3.13/site-packages/django/core/handlers/wsgi.py", line 124, in __call__
2025-09-07 23:29:10,558:     response = self.get_response(request)
2025-09-07 23:29:10,558: 
2025-09-07 23:29:10,558:   File "/home/buddyskincare/.virtualenvs/venv/lib/python3.13/site-packages/django/core/handlers/base.py", line 140, in get_response
2025-09-07 23:29:10,559:     response = self._middleware_chain(request)
2025-09-07 23:29:10,559: 
2025-09-07 23:29:10,559:   File "/home/buddyskincare/.virtualenvs/venv/lib/python3.13/site-packages/django/core/handlers/exception.py", line 57, in inner
2025-09-07 23:29:10,559:     response = response_for_exception(request, exc)
2025-09-07 23:29:10,559: 
2025-09-07 23:29:10,559:   File "/home/buddyskincare/.virtualenvs/venv/lib/python3.13/site-packages/django/core/handlers/exception.py", line 141, in response_for_exception
2025-09-07 23:29:10,560:     response = handle_uncaught_exception(
2025-09-07 23:29:10,560:         request, get_resolver(get_urlconf()), sys.exc_info()
2025-09-07 23:29:10,560:     )
2025-09-07 23:29:10,560: 
2025-09-07 23:29:10,560:   File "/home/buddyskincare/.virtualenvs/venv/lib/python3.13/site-packages/django/core/handlers/exception.py", line 182, in handle_uncaught_exception
2025-09-07 23:29:10,561:     return debug.technical_500_response(request, *exc_info)
2025-09-07 23:29:10,561:            ~~~~~~~~~~~~~~~~~~~~~~~~~~~~^^^^^^^^^^^^^^^^^^^^
2025-09-07 23:29:10,561: 
2025-09-07 23:29:10,561:   File "/home/buddyskincare/.virtualenvs/venv/lib/python3.13/site-packages/django/views/debug.py", line 69, in technical_500_response
2025-09-07 23:29:10,561:     html = reporter.get_traceback_html()
2025-09-07 23:29:10,562: 
2025-09-07 23:29:10,562:   File "/home/buddyskincare/.virtualenvs/venv/lib/python3.13/site-packages/django/views/debug.py", line 428, in get_traceback_html
2025-09-07 23:29:10,562:     c = Context(self.get_traceback_data(), use_l10n=False)
2025-09-07 23:29:10,562:                 ~~~~~~~~~~~~~~~~~~~~~~~^^
2025-09-07 23:29:10,562: 
2025-09-07 23:29:10,562:   File "/home/buddyskincare/.virtualenvs/venv/lib/python3.13/site-packages/django/views/debug.py", line 411, in get_traceback_data
2025-09-07 23:29:10,562:     c["raising_view_name"] = get_caller(self.request)
2025-09-07 23:29:10,563:                              ~~~~~~~~~~^^^^^^^^^^^^^^
2025-09-07 23:29:10,563: 
2025-09-07 23:29:10,563:   File "/home/buddyskincare/.virtualenvs/venv/lib/python3.13/site-packages/django/views/debug.py", line 102, in get_caller
2025-09-07 23:29:10,563:     resolver_match = resolve(request.path)
2025-09-07 23:29:10,563: 
2025-09-07 23:29:10,563:   File "/home/buddyskincare/.virtualenvs/venv/lib/python3.13/site-packages/django/urls/base.py", line 25, in resolve
2025-09-07 23:29:10,563:     return get_resolver(urlconf).resolve(path)
2025-09-07 23:29:10,564:            ~~~~~~~~~~~~~~~~~~~~~~~~~~~~~^^^^^^
2025-09-07 23:29:10,564: 
2025-09-07 23:29:10,564:   File "/home/buddyskincare/.virtualenvs/venv/lib/python3.13/site-packages/django/urls/resolvers.py", line 666, in resolve
2025-09-07 23:29:10,564:     for pattern in self.url_patterns:
2025-09-07 23:29:10,564:                    ^^^^^^^^^^^^^^^^^
2025-09-07 23:29:10,564: 
2025-09-07 23:29:10,565:   File "/home/buddyskincare/.virtualenvs/venv/lib/python3.13/site-packages/django/utils/functional.py", line 47, in __get__
2025-09-07 23:29:10,565:     res = instance.__dict__[self.name] = self.func(instance)
2025-09-07 23:29:10,565:                                          ~~~~~~~~~^^^^^^^^^^
2025-09-07 23:29:10,565: 
2025-09-07 23:29:10,565:   File "/home/buddyskincare/.virtualenvs/venv/lib/python3.13/site-packages/django/urls/resolvers.py", line 718, in url_patterns
2025-09-07 23:29:10,565:     patterns = getattr(self.urlconf_module, "urlpatterns", self.urlconf_module)
2025-09-07 23:29:10,566:                        ^^^^^^^^^^^^^^^^^^^
2025-09-07 23:29:10,566: 
2025-09-07 23:29:10,566:   File "/home/buddyskincare/.virtualenvs/venv/lib/python3.13/site-packages/django/utils/functional.py", line 47, in __get__
2025-09-07 23:29:10,566:     res = instance.__dict__[self.name] = self.func(instance)
2025-09-07 23:29:10,566:                                          ~~~~~~~~~^^^^^^^^^^
2025-09-07 23:29:10,566: 
2025-09-07 23:29:10,567:   File "/home/buddyskincare/.virtualenvs/venv/lib/python3.13/site-packages/django/urls/resolvers.py", line 711, in urlconf_module
2025-09-07 23:29:10,567:     return import_module(self.urlconf_name)
2025-09-07 23:29:10,567: 
2025-09-07 23:29:10,567:   File "/home/buddyskincare/BuddySkincare/BuddyProject/urls.py", line 32, in <module>
2025-09-07 23:29:10,567:     from BuddyApp.views import *
2025-09-07 23:29:10,567: 
2025-09-07 23:29:10,568:   File "/home/buddyskincare/BuddySkincare/BuddyApp/views.py", line 6, in <module>
2025-09-07 23:29:10,568:     from .serializers import *
2025-09-07 23:30:19,872:   File "/home/buddyskincare/BuddySkincare/BuddyApp/serializers.py", line 410
2025-09-07 23:30:19,872: 
2025-09-07 23:30:19,872:     amount_vnd = (Decimal(str(o.total_amount or 0))
2025-09-07 23:30:19,872: 
2025-09-07 23:30:19,873:                  ^
2025-09-07 23:30:19,873: 
2025-09-07 23:30:19,873: SyntaxError: '(' was never closed
2025-09-07 23:30:19,873:   File "/home/buddyskincare/.virtualenvs/venv/lib/python3.13/site-packages/django/core/handlers/wsgi.py", line 124, in __call__
2025-09-07 23:30:19,873:     response = self.get_response(request)
2025-09-07 23:30:19,874: 
2025-09-07 23:30:19,874:   File "/home/buddyskincare/.virtualenvs/venv/lib/python3.13/site-packages/django/core/handlers/base.py", line 140, in get_response
2025-09-07 23:30:19,874:     response = self._middleware_chain(request)
2025-09-07 23:30:19,874: 
2025-09-07 23:30:19,874:   File "/home/buddyskincare/.virtualenvs/venv/lib/python3.13/site-packages/django/core/handlers/exception.py", line 57, in inner
2025-09-07 23:30:19,874:     response = response_for_exception(request, exc)
2025-09-07 23:30:19,875: 
2025-09-07 23:30:19,875:   File "/home/buddyskincare/.virtualenvs/venv/lib/python3.13/site-packages/django/core/handlers/exception.py", line 141, in response_for_exception
2025-09-07 23:30:19,875:     response = handle_uncaught_exception(
2025-09-07 23:30:19,875:         request, get_resolver(get_urlconf()), sys.exc_info()
2025-09-07 23:30:19,875:     )
2025-09-07 23:30:19,875: 
2025-09-07 23:30:19,876:   File "/home/buddyskincare/.virtualenvs/venv/lib/python3.13/site-packages/django/core/handlers/exception.py", line 182, in handle_uncaught_exception
2025-09-07 23:30:19,876:     return debug.technical_500_response(request, *exc_info)
2025-09-07 23:30:19,876:            ~~~~~~~~~~~~~~~~~~~~~~~~~~~~^^^^^^^^^^^^^^^^^^^^
2025-09-07 23:30:19,876: 
2025-09-07 23:30:19,876:   File "/home/buddyskincare/.virtualenvs/venv/lib/python3.13/site-packages/django/views/debug.py", line 69, in technical_500_response
2025-09-07 23:30:19,876:     html = reporter.get_traceback_html()
2025-09-07 23:30:19,877: 
2025-09-07 23:30:19,877:   File "/home/buddyskincare/.virtualenvs/venv/lib/python3.13/site-packages/django/views/debug.py", line 428, in get_traceback_html
2025-09-07 23:30:19,877:     c = Context(self.get_traceback_data(), use_l10n=False)
2025-09-07 23:30:19,877:                 ~~~~~~~~~~~~~~~~~~~~~~~^^
2025-09-07 23:30:19,877: 
2025-09-07 23:30:19,877:   File "/home/buddyskincare/.virtualenvs/venv/lib/python3.13/site-packages/django/views/debug.py", line 411, in get_traceback_data
2025-09-07 23:30:19,878:     c["raising_view_name"] = get_caller(self.request)
2025-09-07 23:30:19,878:                              ~~~~~~~~~~^^^^^^^^^^^^^^
2025-09-07 23:30:19,878: 
2025-09-07 23:30:19,878:   File "/home/buddyskincare/.virtualenvs/venv/lib/python3.13/site-packages/django/views/debug.py", line 102, in get_caller
2025-09-07 23:30:19,878:     resolver_match = resolve(request.path)
2025-09-07 23:30:19,879: 
2025-09-07 23:30:19,879:   File "/home/buddyskincare/.virtualenvs/venv/lib/python3.13/site-packages/django/urls/base.py", line 25, in resolve
2025-09-07 23:30:19,879:     return get_resolver(urlconf).resolve(path)
2025-09-07 23:30:19,879:            ~~~~~~~~~~~~~~~~~~~~~~~~~~~~~^^^^^^
2025-09-07 23:30:19,879: 
2025-09-07 23:30:19,879:   File "/home/buddyskincare/.virtualenvs/venv/lib/python3.13/site-packages/django/urls/resolvers.py", line 666, in resolve
2025-09-07 23:30:19,880:     for pattern in self.url_patterns:
2025-09-07 23:30:19,880:                    ^^^^^^^^^^^^^^^^^
2025-09-07 23:30:19,880: 
2025-09-07 23:30:19,880:   File "/home/buddyskincare/.virtualenvs/venv/lib/python3.13/site-packages/django/utils/functional.py", line 47, in __get__
2025-09-07 23:30:19,880:     res = instance.__dict__[self.name] = self.func(instance)
2025-09-07 23:30:19,880:                                          ~~~~~~~~~^^^^^^^^^^
2025-09-07 23:30:19,881: 
2025-09-07 23:30:19,881:   File "/home/buddyskincare/.virtualenvs/venv/lib/python3.13/site-packages/django/urls/resolvers.py", line 718, in url_patterns
2025-09-07 23:30:19,881:     patterns = getattr(self.urlconf_module, "urlpatterns", self.urlconf_module)
2025-09-07 23:30:19,881:                        ^^^^^^^^^^^^^^^^^^^
2025-09-07 23:30:19,881: 
2025-09-07 23:30:19,881:   File "/home/buddyskincare/.virtualenvs/venv/lib/python3.13/site-packages/django/utils/functional.py", line 47, in __get__
2025-09-07 23:30:19,881:     res = instance.__dict__[self.name] = self.func(instance)
2025-09-07 23:30:19,882:                                          ~~~~~~~~~^^^^^^^^^^
2025-09-07 23:30:19,882: 
2025-09-07 23:30:19,882:   File "/home/buddyskincare/.virtualenvs/venv/lib/python3.13/site-packages/django/urls/resolvers.py", line 711, in urlconf_module
2025-09-07 23:30:19,882:     return import_module(self.urlconf_name)
2025-09-07 23:30:19,882: 
2025-09-07 23:30:19,882:   File "/home/buddyskincare/BuddySkincare/BuddyProject/urls.py", line 32, in <module>
2025-09-07 23:30:19,883:     from BuddyApp.views import *
2025-09-07 23:30:19,883: 
2025-09-07 23:30:19,883:   File "/home/buddyskincare/BuddySkincare/BuddyApp/views.py", line 6, in <module>
2025-09-07 23:30:19,883:     from .serializers import *
2025-09-07 23:30:19,853: Error running WSGI application
2025-09-07 23:30:38,186: Error running WSGI application
2025-09-07 23:30:38,197:   File "/home/buddyskincare/BuddySkincare/BuddyApp/serializers.py", line 410
2025-09-07 23:30:38,197: 
2025-09-07 23:30:38,197:     amount_vnd = (Decimal(str(o.total_amount or 0))
2025-09-07 23:30:38,197: 
2025-09-07 23:30:38,197:                  ^
2025-09-07 23:30:38,197: 
2025-09-07 23:30:38,197: SyntaxError: '(' was never closed
2025-09-07 23:30:38,197:   File "/home/buddyskincare/.virtualenvs/venv/lib/python3.13/site-packages/django/core/handlers/wsgi.py", line 124, in __call__
2025-09-07 23:30:38,197:     response = self.get_response(request)
2025-09-07 23:30:38,197: 
2025-09-07 23:30:38,198:   File "/home/buddyskincare/.virtualenvs/venv/lib/python3.13/site-packages/django/core/handlers/base.py", line 140, in get_response
2025-09-07 23:30:38,199: 
2025-09-07 23:30:38,199:   File "/home/buddyskincare/.virtualenvs/venv/lib/python3.13/site-packages/django/views/debug.py", line 428, in get_traceback_html
2025-09-07 23:30:38,199:     c = Context(self.get_traceback_data(), use_l10n=False)
2025-09-07 23:30:38,199:                 ~~~~~~~~~~~~~~~~~~~~~~~^^
2025-09-07 23:30:38,199: 
2025-09-07 23:30:38,200:   File "/home/buddyskincare/.virtualenvs/venv/lib/python3.13/site-packages/django/views/debug.py", line 411, in get_traceback_data
2025-09-07 23:30:38,200:     c["raising_view_name"] = get_caller(self.request)
2025-09-07 23:30:38,200:                              ~~~~~~~~~~^^^^^^^^^^^^^^
2025-09-07 23:30:38,200: 
2025-09-07 23:30:38,200:   File "/home/buddyskincare/.virtualenvs/venv/lib/python3.13/site-packages/django/views/debug.py", line 102, in get_caller
2025-09-07 23:30:38,200:     resolver_match = resolve(request.path)
2025-09-07 23:30:38,200: 
2025-09-07 23:30:38,200:   File "/home/buddyskincare/.virtualenvs/venv/lib/python3.13/site-packages/django/urls/base.py", line 25, in resolve
2025-09-07 23:30:38,200:     return get_resolver(urlconf).resolve(path)
2025-09-07 23:30:38,200:            ~~~~~~~~~~~~~~~~~~~~~~~~~~~~~^^^^^^
2025-09-07 23:30:38,201: 
2025-09-07 23:30:38,201:   File "/home/buddyskincare/.virtualenvs/venv/lib/python3.13/site-packages/django/urls/resolvers.py", line 666, in resolve
2025-09-07 23:30:38,201:     for pattern in self.url_patterns:
2025-09-07 23:30:38,201:                    ^^^^^^^^^^^^^^^^^
2025-09-07 23:30:38,201: 
2025-09-07 23:30:38,201:   File "/home/buddyskincare/.virtualenvs/venv/lib/python3.13/site-packages/django/utils/functional.py", line 47, in __get__
2025-09-07 23:30:38,201:     res = instance.__dict__[self.name] = self.func(instance)
2025-09-07 23:30:38,201:                                          ~~~~~~~~~^^^^^^^^^^
2025-09-07 23:30:38,201: 
2025-09-07 23:30:38,201:   File "/home/buddyskincare/.virtualenvs/venv/lib/python3.13/site-packages/django/urls/resolvers.py", line 718, in url_patterns
2025-09-07 23:30:38,201:     patterns = getattr(self.urlconf_module, "urlpatterns", self.urlconf_module)
2025-09-07 23:30:38,201:                        ^^^^^^^^^^^^^^^^^^^
2025-09-07 23:30:38,202: 
2025-09-07 23:30:38,202:   File "/home/buddyskincare/.virtualenvs/venv/lib/python3.13/site-packages/django/utils/functional.py", line 47, in __get__
2025-09-07 23:30:38,202:     res = instance.__dict__[self.name] = self.func(instance)
2025-09-07 23:30:38,202:                                          ~~~~~~~~~^^^^^^^^^^
2025-09-07 23:30:38,202: 
2025-09-07 23:30:38,202:   File "/home/buddyskincare/.virtualenvs/venv/lib/python3.13/site-packages/django/urls/resolvers.py", line 711, in urlconf_module
2025-09-07 23:30:38,202:     return import_module(self.urlconf_name)
2025-09-07 23:30:38,202: 
2025-09-07 23:30:38,202:   File "/home/buddyskincare/BuddySkincare/BuddyProject/urls.py", line 32, in <module>
2025-09-07 23:30:38,202:     from BuddyApp.views import *
2025-09-07 23:30:38,202: 
2025-09-07 23:30:38,202:   File "/home/buddyskincare/BuddySkincare/BuddyApp/views.py", line 6, in <module>
2025-09-07 23:30:38,202:     from .serializers import *
2025-09-07 23:30:38,198:     response = self._middleware_chain(request)
2025-09-07 23:30:38,198: 
2025-09-07 23:30:38,198:   File "/home/buddyskincare/.virtualenvs/venv/lib/python3.13/site-packages/django/core/handlers/exception.py", line 57, in inner
2025-09-07 23:30:38,198:     response = response_for_exception(request, exc)
2025-09-07 23:30:38,198: 
2025-09-07 23:30:38,198:   File "/home/buddyskincare/.virtualenvs/venv/lib/python3.13/site-packages/django/core/handlers/exception.py", line 141, in response_for_exception
2025-09-07 23:30:38,198:     response = handle_uncaught_exception(
2025-09-07 23:30:38,198:         request, get_resolver(get_urlconf()), sys.exc_info()
2025-09-07 23:30:38,198:     )
2025-09-07 23:30:38,198: 
2025-09-07 23:30:38,198:   File "/home/buddyskincare/.virtualenvs/venv/lib/python3.13/site-packages/django/core/handlers/exception.py", line 182, in handle_uncaught_exception
2025-09-07 23:30:38,199:     return debug.technical_500_response(request, *exc_info)
2025-09-07 23:30:38,199:            ~~~~~~~~~~~~~~~~~~~~~~~~~~~~^^^^^^^^^^^^^^^^^^^^
2025-09-07 23:30:38,199: 
2025-09-07 23:30:38,199:   File "/home/buddyskincare/.virtualenvs/venv/lib/python3.13/site-packages/django/views/debug.py", line 69, in technical_500_response
2025-09-07 23:30:38,199:     html = reporter.get_traceback_html()
2025-09-08 11:44:08,723: Not Found: /analytics/day
2025-09-08 15:11:25,674: Internal Server Error: /auth/login/
Traceback (most recent call last):
  File "/home/buddyskincare/.virtualenvs/venv/lib/python3.13/site-packages/django/core/handlers/exception.py", line 55, in inner
    response = get_response(request)
  File "/home/buddyskincare/.virtualenvs/venv/lib/python3.13/site-packages/django/core/handlers/base.py", line 197, in _get_response
    response = wrapped_callback(request, *callback_args, **callback_kwargs)
  File "/home/buddyskincare/.virtualenvs/venv/lib/python3.13/site-packages/django/views/decorators/csrf.py", line 65, in _view_wrapper
    return view_func(request, *args, **kwargs)
  File "/home/buddyskincare/.virtualenvs/venv/lib/python3.13/site-packages/django/views/generic/base.py", line 105, in view
    return self.dispatch(request, *args, **kwargs)
           ~~~~~~~~~~~~~^^^^^^^^^^^^^^^^^^^^^^^^^^
  File "/home/buddyskincare/.virtualenvs/venv/lib/python3.13/site-packages/rest_framework/views.py", line 515, in dispatch
    response = self.handle_exception(exc)
  File "/home/buddyskincare/.virtualenvs/venv/lib/python3.13/site-packages/rest_framework/views.py", line 475, in handle_exception
    self.raise_uncaught_exception(exc)
    ~~~~~~~~~~~~~~~~~~~~~~~~~~~~~^^^^^
  File "/home/buddyskincare/.virtualenvs/venv/lib/python3.13/site-packages/rest_framework/views.py", line 486, in raise_uncaught_exception
    raise exc
  File "/home/buddyskincare/.virtualenvs/venv/lib/python3.13/site-packages/rest_framework/views.py", line 512, in dispatch
    response = handler(request, *args, **kwargs)
  File "/home/buddyskincare/BuddySkincare/BuddyApp/views.py", line 689, in post
    if serializer.is_valid():
       ~~~~~~~~~~~~~~~~~~~^^
  File "/home/buddyskincare/.virtualenvs/venv/lib/python3.13/site-packages/rest_framework/serializers.py", line 225, in is_valid
    self._validated_data = self.run_validation(self.initial_data)
                           ~~~~~~~~~~~~~~~~~~~^^^^^^^^^^^^^^^^^^^
  File "/home/buddyskincare/.virtualenvs/venv/lib/python3.13/site-packages/rest_framework/serializers.py", line 447, in run_validation
    value = self.validate(value)
  File "/home/buddyskincare/BuddySkincare/BuddyApp/serializers.py", line 112, in validate
    user = authenticate(request=self.context.get('request'),
                        phone_number=phone_number, password=password)
  File "/home/buddyskincare/.virtualenvs/venv/lib/python3.13/site-packages/django/views/decorators/debug.py", line 75, in sensitive_variables_wrapper
    return func(*func_args, **func_kwargs)
  File "/home/buddyskincare/.virtualenvs/venv/lib/python3.13/site-packages/django/contrib/auth/__init__.py", line 112, in authenticate
    for backend, backend_path in _get_compatible_backends(request, **credentials):
                                 ~~~~~~~~~~~~~~~~~~~~~~~~^^^^^^^^^^^^^^^^^^^^^^^^
  File "/home/buddyskincare/.virtualenvs/venv/lib/python3.13/site-packages/django/contrib/auth/__init__.py", line 44, in _get_compatible_backends
    for backend, backend_path in _get_backends(return_tuples=True):
                                 ~~~~~~~~~~~~~^^^^^^^^^^^^^^^^^^^^
  File "/home/buddyskincare/.virtualenvs/venv/lib/python3.13/site-packages/django/contrib/auth/__init__.py", line 29, in _get_backends
    backend = load_backend(backend_path)
  File "/home/buddyskincare/.virtualenvs/venv/lib/python3.13/site-packages/django/contrib/auth/__init__.py", line 23, in load_backend
    return import_string(path)()
           ~~~~~~~~~~~~~~~~~~~^^
TypeError: BaseAuth.__init__() missing 1 required positional argument: 'strategy'
2025-09-09 08:11:34,363: Not Found: /favicon.ico
2025-09-09 08:23:08,131: Validating token with client ID: 821773612134-su4afp8ac99s2l6cpvsmf0ti7p2d61aq.apps.googleusercontent.com
2025-09-09 08:23:08,131: Token length: 1202
2025-09-09 08:23:08,131: Token starts with: eyJhbGciOiJSUzI1NiIsImtpZCI6IjljNjI1MTU4Nzk1MDg0NG...
2025-09-09 08:23:08,131: Token ends with: ...TudRW8_cL0AxQWPboWyA
2025-09-09 08:23:08,435: Token validation successful!
2025-09-09 08:23:08,435: Email: buddyskincarevn@gmail.com
2025-09-09 08:23:08,435: Name: buddy cosmetic
2025-09-09 08:23:08,435: Sub: 117980497165894567099
2025-09-09 08:23:08,436: Aud: 821773612134-su4afp8ac99s2l6cpvsmf0ti7p2d61aq.apps.googleusercontent.com
2025-09-09 09:03:17,683: Bad Request: /orders/
2025-09-09 09:15:20,495: Bad Request: /orders/
2025-09-09 09:19:24,713: Not Found: /admin/orders/36
2025-09-09 10:44:26,534: Bad Request: /auth/register/
2025-09-09 10:44:26,544: Not Found: /users/register/
2025-09-09 10:44:36,193: Not Found: /users/register/
2025-09-09 10:44:44,645: Not Found: /favicon.ico
2025-09-09 10:48:21,652: Not Found: /users/register/
2025-09-09 10:48:21,668: Bad Request: /auth/register/
2025-09-09 10:48:32,901: Not Found: /favicon.ico
2025-09-09 11:00:43,070: Not Found: /favicon.ico
2025-09-09 11:43:55,246: Not Found: /favicon.ico
2025-09-09 11:55:09,741: Not Found: /favicon.ico
2025-09-09 12:08:01,839: Internal Server Error: /admin/BuddyApp/product/
Traceback (most recent call last):
  File "/home/buddyskincare/.virtualenvs/venv/lib/python3.13/site-packages/django/core/handlers/exception.py", line 55, in inner
    response = get_response(request)
  File "/home/buddyskincare/.virtualenvs/venv/lib/python3.13/site-packages/django/core/handlers/base.py", line 197, in _get_response
    response = wrapped_callback(request, *callback_args, **callback_kwargs)
  File "/home/buddyskincare/.virtualenvs/venv/lib/python3.13/site-packages/django/contrib/admin/options.py", line 719, in wrapper
    return self.admin_site.admin_view(view)(*args, **kwargs)
           ~~~~~~~~~~~~~~~~~~~~~~~~~~~~~~~~^^^^^^^^^^^^^^^^^
  File "/home/buddyskincare/.virtualenvs/venv/lib/python3.13/site-packages/django/utils/decorators.py", line 192, in _view_wrapper
    result = _process_exception(request, e)
  File "/home/buddyskincare/.virtualenvs/venv/lib/python3.13/site-packages/django/utils/decorators.py", line 190, in _view_wrapper
    response = view_func(request, *args, **kwargs)
  File "/home/buddyskincare/.virtualenvs/venv/lib/python3.13/site-packages/django/views/decorators/cache.py", line 80, in _view_wrapper
    response = view_func(request, *args, **kwargs)
  File "/home/buddyskincare/.virtualenvs/venv/lib/python3.13/site-packages/django/contrib/admin/sites.py", line 246, in inner
    return view(request, *args, **kwargs)
  File "/home/buddyskincare/.virtualenvs/venv/lib/python3.13/site-packages/django/utils/decorators.py", line 48, in _wrapper
    return bound_method(*args, **kwargs)
  File "/home/buddyskincare/.virtualenvs/venv/lib/python3.13/site-packages/django/utils/decorators.py", line 192, in _view_wrapper
    result = _process_exception(request, e)
  File "/home/buddyskincare/.virtualenvs/venv/lib/python3.13/site-packages/django/utils/decorators.py", line 190, in _view_wrapper
    response = view_func(request, *args, **kwargs)
  File "/home/buddyskincare/.virtualenvs/venv/lib/python3.13/site-packages/django/contrib/admin/options.py", line 2139, in changelist_view
    FormSet = self.get_changelist_formset(request)
  File "/home/buddyskincare/.virtualenvs/venv/lib/python3.13/site-packages/django/contrib/admin/options.py", line 925, in get_changelist_formset
    return modelformset_factory(
        self.model,
    ...<3 lines>...
        **defaults,
    )
  File "/home/buddyskincare/.virtualenvs/venv/lib/python3.13/site-packages/django/forms/models.py", line 1051, in modelformset_factory
    form = modelform_factory(
        model,
    ...<9 lines>...
        field_classes=field_classes,
    )
  File "/home/buddyskincare/.virtualenvs/venv/lib/python3.13/site-packages/django/forms/models.py", line 654, in modelform_factory
    return type(form)(class_name, (form,), form_class_attrs)
           ~~~~~~~~~~^^^^^^^^^^^^^^^^^^^^^^^^^^^^^^^^^^^^^^^
  File "/home/buddyskincare/.virtualenvs/venv/lib/python3.13/site-packages/django/forms/models.py", line 334, in __new__
    raise FieldError(message)
django.core.exceptions.FieldError: Unknown field(s) (display_tags) specified for Product
2025-09-09 12:09:41,848: Error running WSGI application
2025-09-09 12:09:41,863: NameError: name 'forms' is not defined
2025-09-09 12:09:41,863:   File "/var/www/buddyskincare_pythonanywhere_com_wsgi.py", line 22, in <module>
2025-09-09 12:09:41,864:     application = get_wsgi_application()
2025-09-09 12:09:41,864: 
2025-09-09 12:09:41,864:   File "/home/buddyskincare/.virtualenvs/venv/lib/python3.13/site-packages/django/core/wsgi.py", line 12, in get_wsgi_application
2025-09-09 12:09:41,864:     django.setup(set_prefix=False)
2025-09-09 12:09:41,864:     ~~~~~~~~~~~~^^^^^^^^^^^^^^^^^^
2025-09-09 12:09:41,865: 
2025-09-09 12:09:41,865:   File "/home/buddyskincare/.virtualenvs/venv/lib/python3.13/site-packages/django/__init__.py", line 24, in setup
2025-09-09 12:09:41,865:     apps.populate(settings.INSTALLED_APPS)
2025-09-09 12:09:41,865:     ~~~~~~~~~~~~~^^^^^^^^^^^^^^^^^^^^^^^^^
2025-09-09 12:09:41,865: 
2025-09-09 12:09:41,865:   File "/home/buddyskincare/.virtualenvs/venv/lib/python3.13/site-packages/django/apps/registry.py", line 124, in populate
2025-09-09 12:09:41,865:     app_config.ready()
2025-09-09 12:09:41,865:     ~~~~~~~~~~~~~~~~^^
2025-09-09 12:09:41,865: 
2025-09-09 12:09:41,865:   File "/home/buddyskincare/.virtualenvs/venv/lib/python3.13/site-packages/django/contrib/admin/apps.py", line 27, in ready
2025-09-09 12:09:41,866:     self.module.autodiscover()
2025-09-09 12:09:41,866:     ~~~~~~~~~~~~~~~~~~~~~~~~^^
2025-09-09 12:09:41,866: 
2025-09-09 12:09:41,866:   File "/home/buddyskincare/.virtualenvs/venv/lib/python3.13/site-packages/django/contrib/admin/__init__.py", line 52, in autodiscover
2025-09-09 12:09:41,866:     autodiscover_modules("admin", register_to=site)
2025-09-09 12:09:41,866:     ~~~~~~~~~~~~~~~~~~~~^^^^^^^^^^^^^^^^^^^^^^^^^^^
2025-09-09 12:09:41,866: 
2025-09-09 12:09:41,866:   File "/home/buddyskincare/.virtualenvs/venv/lib/python3.13/site-packages/django/utils/module_loading.py", line 58, in autodiscover_modules
2025-09-09 12:09:41,866:     import_module("%s.%s" % (app_config.name, module_to_search))
2025-09-09 12:09:41,866:     ~~~~~~~~~~~~~^^^^^^^^^^^^^^^^^^^^^^^^^^^^^^^^^^^^^^^^^^^^^^^
2025-09-09 12:09:41,866: 
2025-09-09 12:09:41,866:   File "/home/buddyskincare/BuddySkincare/BuddyApp/admin.py", line 120, in <module>
2025-09-09 12:09:41,867:     class ProductAdminForm(forms.ModelForm):
2025-09-09 12:09:41,867:                            ^^^^^
2025-09-09 12:09:41,867: ***************************************************
2025-09-09 12:09:41,867: If you're seeing an import error and don't know why,
2025-09-09 12:09:41,867: we have a dedicated help page to help you debug: 
2025-09-09 12:09:41,867: https://help.pythonanywhere.com/pages/DebuggingImportError/
2025-09-09 12:09:41,867: ***************************************************
2025-09-09 12:09:44,736: Error running WSGI application
2025-09-09 12:09:44,739: NameError: name 'forms' is not defined
2025-09-09 12:09:44,740:   File "/var/www/buddyskincare_pythonanywhere_com_wsgi.py", line 22, in <module>
2025-09-09 12:09:44,740:     application = get_wsgi_application()
2025-09-09 12:09:44,740: 
2025-09-09 12:09:44,740:   File "/home/buddyskincare/.virtualenvs/venv/lib/python3.13/site-packages/django/core/wsgi.py", line 12, in get_wsgi_application
2025-09-09 12:09:44,740:     django.setup(set_prefix=False)
2025-09-09 12:09:44,740:     ~~~~~~~~~~~~^^^^^^^^^^^^^^^^^^
2025-09-09 12:09:44,741: 
2025-09-09 12:09:44,741:   File "/home/buddyskincare/.virtualenvs/venv/lib/python3.13/site-packages/django/__init__.py", line 24, in setup
2025-09-09 12:09:44,741:     apps.populate(settings.INSTALLED_APPS)
2025-09-09 12:09:44,741:     ~~~~~~~~~~~~~^^^^^^^^^^^^^^^^^^^^^^^^^
2025-09-09 12:09:44,741: 
2025-09-09 12:09:44,742:   File "/home/buddyskincare/.virtualenvs/venv/lib/python3.13/site-packages/django/apps/registry.py", line 124, in populate
2025-09-09 12:09:44,742:     app_config.ready()
2025-09-09 12:09:44,742:     ~~~~~~~~~~~~~~~~^^
2025-09-09 12:09:44,742: 
2025-09-09 12:09:44,742:   File "/home/buddyskincare/.virtualenvs/venv/lib/python3.13/site-packages/django/contrib/admin/apps.py", line 27, in ready
2025-09-09 12:09:44,742:     self.module.autodiscover()
2025-09-09 12:09:44,742:     ~~~~~~~~~~~~~~~~~~~~~~~~^^
2025-09-09 12:09:44,743: 
2025-09-09 12:09:44,743:   File "/home/buddyskincare/.virtualenvs/venv/lib/python3.13/site-packages/django/contrib/admin/__init__.py", line 52, in autodiscover
2025-09-09 12:09:44,743:     autodiscover_modules("admin", register_to=site)
2025-09-09 12:09:44,743:     ~~~~~~~~~~~~~~~~~~~~^^^^^^^^^^^^^^^^^^^^^^^^^^^
2025-09-09 12:09:44,743: 
2025-09-09 12:09:44,743:   File "/home/buddyskincare/.virtualenvs/venv/lib/python3.13/site-packages/django/utils/module_loading.py", line 58, in autodiscover_modules
2025-09-09 12:09:44,744:     import_module("%s.%s" % (app_config.name, module_to_search))
2025-09-09 12:09:44,744:     ~~~~~~~~~~~~~^^^^^^^^^^^^^^^^^^^^^^^^^^^^^^^^^^^^^^^^^^^^^^^
2025-09-09 12:09:44,744: 
2025-09-09 12:09:44,744:   File "/home/buddyskincare/BuddySkincare/BuddyApp/admin.py", line 120, in <module>
2025-09-09 12:09:44,744:     class ProductAdminForm(forms.ModelForm):
2025-09-09 12:09:44,744:                            ^^^^^
2025-09-09 12:09:44,745: ***************************************************
2025-09-09 12:09:44,745: If you're seeing an import error and don't know why,
2025-09-09 12:09:44,745: we have a dedicated help page to help you debug: 
2025-09-09 12:09:44,745: https://help.pythonanywhere.com/pages/DebuggingImportError/
2025-09-09 12:09:44,745: ***************************************************
2025-09-09 12:12:59,208: Not Found: /favicon.ico
2025-09-09 12:13:15,093: Internal Server Error: /admin/login/
Traceback (most recent call last):
  File "/home/buddyskincare/.virtualenvs/venv/lib/python3.13/site-packages/django/core/handlers/exception.py", line 55, in inner
    response = get_response(request)
  File "/home/buddyskincare/.virtualenvs/venv/lib/python3.13/site-packages/django/core/handlers/base.py", line 197, in _get_response
    response = wrapped_callback(request, *callback_args, **callback_kwargs)
  File "/home/buddyskincare/.virtualenvs/venv/lib/python3.13/site-packages/django/utils/decorators.py", line 48, in _wrapper
    return bound_method(*args, **kwargs)
  File "/home/buddyskincare/.virtualenvs/venv/lib/python3.13/site-packages/django/views/decorators/cache.py", line 80, in _view_wrapper
    response = view_func(request, *args, **kwargs)
  File "/home/buddyskincare/.virtualenvs/venv/lib/python3.13/site-packages/django/contrib/admin/sites.py", line 430, in login
    **self.each_context(request),
      ~~~~~~~~~~~~~~~~~^^^^^^^^^
  File "/home/buddyskincare/.virtualenvs/venv/lib/python3.13/site-packages/django/contrib/admin/sites.py", line 343, in each_context
    "available_apps": self.get_app_list(request),
                      ~~~~~~~~~~~~~~~~~^^^^^^^^^
  File "/home/buddyskincare/.virtualenvs/venv/lib/python3.13/site-packages/django/contrib/admin/sites.py", line 546, in get_app_list
    app_dict = self._build_app_dict(request, app_label)
  File "/home/buddyskincare/.virtualenvs/venv/lib/python3.13/site-packages/django/contrib/admin/sites.py", line 488, in _build_app_dict
    has_module_perms = model_admin.has_module_permission(request)
  File "/home/buddyskincare/.virtualenvs/venv/lib/python3.13/site-packages/django/contrib/admin/options.py", line 641, in has_module_permission
    return request.user.has_module_perms(self.opts.app_label)
           ~~~~~~~~~~~~~~~~~~~~~~~~~~~~~^^^^^^^^^^^^^^^^^^^^^
  File "/home/buddyskincare/.virtualenvs/venv/lib/python3.13/site-packages/django/contrib/auth/models.py", line 620, in has_module_perms
    return _user_has_module_perms(self, module)
  File "/home/buddyskincare/.virtualenvs/venv/lib/python3.13/site-packages/django/contrib/auth/models.py", line 293, in _user_has_module_perms
    for backend in auth.get_backends():
                   ~~~~~~~~~~~~~~~~~^^
  File "/home/buddyskincare/.virtualenvs/venv/lib/python3.13/site-packages/django/contrib/auth/__init__.py", line 40, in get_backends
    return _get_backends(return_tuples=False)
  File "/home/buddyskincare/.virtualenvs/venv/lib/python3.13/site-packages/django/contrib/auth/__init__.py", line 29, in _get_backends
    backend = load_backend(backend_path)
  File "/home/buddyskincare/.virtualenvs/venv/lib/python3.13/site-packages/django/contrib/auth/__init__.py", line 23, in load_backend
    return import_string(path)()
           ~~~~~~~~~~~~~~~~~~~^^
TypeError: BaseAuth.__init__() missing 1 required positional argument: 'strategy'
2025-09-09 12:13:23,937: Internal Server Error: /admin/login/
Traceback (most recent call last):
  File "/home/buddyskincare/.virtualenvs/venv/lib/python3.13/site-packages/django/core/handlers/exception.py", line 55, in inner
    response = get_response(request)
  File "/home/buddyskincare/.virtualenvs/venv/lib/python3.13/site-packages/django/core/handlers/base.py", line 197, in _get_response
    response = wrapped_callback(request, *callback_args, **callback_kwargs)
  File "/home/buddyskincare/.virtualenvs/venv/lib/python3.13/site-packages/django/utils/decorators.py", line 48, in _wrapper
    return bound_method(*args, **kwargs)
  File "/home/buddyskincare/.virtualenvs/venv/lib/python3.13/site-packages/django/views/decorators/cache.py", line 80, in _view_wrapper
    response = view_func(request, *args, **kwargs)
  File "/home/buddyskincare/.virtualenvs/venv/lib/python3.13/site-packages/django/contrib/admin/sites.py", line 430, in login
    **self.each_context(request),
      ~~~~~~~~~~~~~~~~~^^^^^^^^^
  File "/home/buddyskincare/.virtualenvs/venv/lib/python3.13/site-packages/django/contrib/admin/sites.py", line 343, in each_context
    "available_apps": self.get_app_list(request),
                      ~~~~~~~~~~~~~~~~~^^^^^^^^^
  File "/home/buddyskincare/.virtualenvs/venv/lib/python3.13/site-packages/django/contrib/admin/sites.py", line 546, in get_app_list
    app_dict = self._build_app_dict(request, app_label)
  File "/home/buddyskincare/.virtualenvs/venv/lib/python3.13/site-packages/django/contrib/admin/sites.py", line 488, in _build_app_dict
    has_module_perms = model_admin.has_module_permission(request)
  File "/home/buddyskincare/.virtualenvs/venv/lib/python3.13/site-packages/django/contrib/admin/options.py", line 641, in has_module_permission
    return request.user.has_module_perms(self.opts.app_label)
           ~~~~~~~~~~~~~~~~~~~~~~~~~~~~~^^^^^^^^^^^^^^^^^^^^^
  File "/home/buddyskincare/.virtualenvs/venv/lib/python3.13/site-packages/django/contrib/auth/models.py", line 620, in has_module_perms
    return _user_has_module_perms(self, module)
  File "/home/buddyskincare/.virtualenvs/venv/lib/python3.13/site-packages/django/contrib/auth/models.py", line 293, in _user_has_module_perms
    for backend in auth.get_backends():
                   ~~~~~~~~~~~~~~~~~^^
  File "/home/buddyskincare/.virtualenvs/venv/lib/python3.13/site-packages/django/contrib/auth/__init__.py", line 40, in get_backends
    return _get_backends(return_tuples=False)
  File "/home/buddyskincare/.virtualenvs/venv/lib/python3.13/site-packages/django/contrib/auth/__init__.py", line 29, in _get_backends
    backend = load_backend(backend_path)
  File "/home/buddyskincare/.virtualenvs/venv/lib/python3.13/site-packages/django/contrib/auth/__init__.py", line 23, in load_backend
    return import_string(path)()
           ~~~~~~~~~~~~~~~~~~~^^
TypeError: BaseAuth.__init__() missing 1 required positional argument: 'strategy'
2025-09-09 12:13:28,190: Internal Server Error: /admin/login/
Traceback (most recent call last):
  File "/home/buddyskincare/.virtualenvs/venv/lib/python3.13/site-packages/django/core/handlers/exception.py", line 55, in inner
    response = get_response(request)
  File "/home/buddyskincare/.virtualenvs/venv/lib/python3.13/site-packages/django/core/handlers/base.py", line 197, in _get_response
    response = wrapped_callback(request, *callback_args, **callback_kwargs)
  File "/home/buddyskincare/.virtualenvs/venv/lib/python3.13/site-packages/django/utils/decorators.py", line 48, in _wrapper
    return bound_method(*args, **kwargs)
  File "/home/buddyskincare/.virtualenvs/venv/lib/python3.13/site-packages/django/views/decorators/cache.py", line 80, in _view_wrapper
    response = view_func(request, *args, **kwargs)
  File "/home/buddyskincare/.virtualenvs/venv/lib/python3.13/site-packages/django/contrib/admin/sites.py", line 430, in login
    **self.each_context(request),
      ~~~~~~~~~~~~~~~~~^^^^^^^^^
  File "/home/buddyskincare/.virtualenvs/venv/lib/python3.13/site-packages/django/contrib/admin/sites.py", line 343, in each_context
    "available_apps": self.get_app_list(request),
                      ~~~~~~~~~~~~~~~~~^^^^^^^^^
  File "/home/buddyskincare/.virtualenvs/venv/lib/python3.13/site-packages/django/contrib/admin/sites.py", line 546, in get_app_list
    app_dict = self._build_app_dict(request, app_label)
  File "/home/buddyskincare/.virtualenvs/venv/lib/python3.13/site-packages/django/contrib/admin/sites.py", line 488, in _build_app_dict
    has_module_perms = model_admin.has_module_permission(request)
  File "/home/buddyskincare/.virtualenvs/venv/lib/python3.13/site-packages/django/contrib/admin/options.py", line 641, in has_module_permission
    return request.user.has_module_perms(self.opts.app_label)
           ~~~~~~~~~~~~~~~~~~~~~~~~~~~~~^^^^^^^^^^^^^^^^^^^^^
  File "/home/buddyskincare/.virtualenvs/venv/lib/python3.13/site-packages/django/contrib/auth/models.py", line 620, in has_module_perms
    return _user_has_module_perms(self, module)
  File "/home/buddyskincare/.virtualenvs/venv/lib/python3.13/site-packages/django/contrib/auth/models.py", line 293, in _user_has_module_perms
    for backend in auth.get_backends():
                   ~~~~~~~~~~~~~~~~~^^
  File "/home/buddyskincare/.virtualenvs/venv/lib/python3.13/site-packages/django/contrib/auth/__init__.py", line 40, in get_backends
    return _get_backends(return_tuples=False)
  File "/home/buddyskincare/.virtualenvs/venv/lib/python3.13/site-packages/django/contrib/auth/__init__.py", line 29, in _get_backends
    backend = load_backend(backend_path)
  File "/home/buddyskincare/.virtualenvs/venv/lib/python3.13/site-packages/django/contrib/auth/__init__.py", line 23, in load_backend
    return import_string(path)()
           ~~~~~~~~~~~~~~~~~~~^^
TypeError: BaseAuth.__init__() missing 1 required positional argument: 'strategy'
2025-09-09 12:16:22,644: Internal Server Error: /admin/login/
Traceback (most recent call last):
  File "/home/buddyskincare/.virtualenvs/venv/lib/python3.13/site-packages/django/core/handlers/exception.py", line 55, in inner
    response = get_response(request)
  File "/home/buddyskincare/.virtualenvs/venv/lib/python3.13/site-packages/django/core/handlers/base.py", line 197, in _get_response
    response = wrapped_callback(request, *callback_args, **callback_kwargs)
  File "/home/buddyskincare/.virtualenvs/venv/lib/python3.13/site-packages/django/utils/decorators.py", line 48, in _wrapper
    return bound_method(*args, **kwargs)
  File "/home/buddyskincare/.virtualenvs/venv/lib/python3.13/site-packages/django/views/decorators/cache.py", line 80, in _view_wrapper
    response = view_func(request, *args, **kwargs)
  File "/home/buddyskincare/.virtualenvs/venv/lib/python3.13/site-packages/django/contrib/admin/sites.py", line 430, in login
    **self.each_context(request),
      ~~~~~~~~~~~~~~~~~^^^^^^^^^
  File "/home/buddyskincare/.virtualenvs/venv/lib/python3.13/site-packages/django/contrib/admin/sites.py", line 343, in each_context
    "available_apps": self.get_app_list(request),
                      ~~~~~~~~~~~~~~~~~^^^^^^^^^
  File "/home/buddyskincare/.virtualenvs/venv/lib/python3.13/site-packages/django/contrib/admin/sites.py", line 546, in get_app_list
    app_dict = self._build_app_dict(request, app_label)
  File "/home/buddyskincare/.virtualenvs/venv/lib/python3.13/site-packages/django/contrib/admin/sites.py", line 488, in _build_app_dict
    has_module_perms = model_admin.has_module_permission(request)
  File "/home/buddyskincare/.virtualenvs/venv/lib/python3.13/site-packages/django/contrib/admin/options.py", line 641, in has_module_permission
    return request.user.has_module_perms(self.opts.app_label)
           ~~~~~~~~~~~~~~~~~~~~~~~~~~~~~^^^^^^^^^^^^^^^^^^^^^
  File "/home/buddyskincare/.virtualenvs/venv/lib/python3.13/site-packages/django/contrib/auth/models.py", line 620, in has_module_perms
    return _user_has_module_perms(self, module)
  File "/home/buddyskincare/.virtualenvs/venv/lib/python3.13/site-packages/django/contrib/auth/models.py", line 293, in _user_has_module_perms
    for backend in auth.get_backends():
                   ~~~~~~~~~~~~~~~~~^^
  File "/home/buddyskincare/.virtualenvs/venv/lib/python3.13/site-packages/django/contrib/auth/__init__.py", line 40, in get_backends
    return _get_backends(return_tuples=False)
  File "/home/buddyskincare/.virtualenvs/venv/lib/python3.13/site-packages/django/contrib/auth/__init__.py", line 29, in _get_backends
    backend = load_backend(backend_path)
  File "/home/buddyskincare/.virtualenvs/venv/lib/python3.13/site-packages/django/contrib/auth/__init__.py", line 23, in load_backend
    return import_string(path)()
           ~~~~~~~~~~~~~~~~~~~^^
TypeError: BaseAuth.__init__() missing 1 required positional argument: 'strategy'
2025-09-09 12:16:22,647: OSError: write error
2025-09-09 12:16:22,937: Internal Server Error: /admin/login/
Traceback (most recent call last):
  File "/home/buddyskincare/.virtualenvs/venv/lib/python3.13/site-packages/django/core/handlers/exception.py", line 55, in inner
    response = get_response(request)
  File "/home/buddyskincare/.virtualenvs/venv/lib/python3.13/site-packages/django/core/handlers/base.py", line 197, in _get_response
    response = wrapped_callback(request, *callback_args, **callback_kwargs)
  File "/home/buddyskincare/.virtualenvs/venv/lib/python3.13/site-packages/django/utils/decorators.py", line 48, in _wrapper
    return bound_method(*args, **kwargs)
  File "/home/buddyskincare/.virtualenvs/venv/lib/python3.13/site-packages/django/views/decorators/cache.py", line 80, in _view_wrapper
    response = view_func(request, *args, **kwargs)
  File "/home/buddyskincare/.virtualenvs/venv/lib/python3.13/site-packages/django/contrib/admin/sites.py", line 430, in login
    **self.each_context(request),
      ~~~~~~~~~~~~~~~~~^^^^^^^^^
  File "/home/buddyskincare/.virtualenvs/venv/lib/python3.13/site-packages/django/contrib/admin/sites.py", line 343, in each_context
    "available_apps": self.get_app_list(request),
                      ~~~~~~~~~~~~~~~~~^^^^^^^^^
  File "/home/buddyskincare/.virtualenvs/venv/lib/python3.13/site-packages/django/contrib/admin/sites.py", line 546, in get_app_list
    app_dict = self._build_app_dict(request, app_label)
  File "/home/buddyskincare/.virtualenvs/venv/lib/python3.13/site-packages/django/contrib/admin/sites.py", line 488, in _build_app_dict
    has_module_perms = model_admin.has_module_permission(request)
  File "/home/buddyskincare/.virtualenvs/venv/lib/python3.13/site-packages/django/contrib/admin/options.py", line 641, in has_module_permission
    return request.user.has_module_perms(self.opts.app_label)
           ~~~~~~~~~~~~~~~~~~~~~~~~~~~~~^^^^^^^^^^^^^^^^^^^^^
  File "/home/buddyskincare/.virtualenvs/venv/lib/python3.13/site-packages/django/contrib/auth/models.py", line 620, in has_module_perms
    return _user_has_module_perms(self, module)
  File "/home/buddyskincare/.virtualenvs/venv/lib/python3.13/site-packages/django/contrib/auth/models.py", line 293, in _user_has_module_perms
    for backend in auth.get_backends():
                   ~~~~~~~~~~~~~~~~~^^
  File "/home/buddyskincare/.virtualenvs/venv/lib/python3.13/site-packages/django/contrib/auth/__init__.py", line 40, in get_backends
    return _get_backends(return_tuples=False)
  File "/home/buddyskincare/.virtualenvs/venv/lib/python3.13/site-packages/django/contrib/auth/__init__.py", line 29, in _get_backends
    backend = load_backend(backend_path)
  File "/home/buddyskincare/.virtualenvs/venv/lib/python3.13/site-packages/django/contrib/auth/__init__.py", line 23, in load_backend
    return import_string(path)()
           ~~~~~~~~~~~~~~~~~~~^^
TypeError: BaseAuth.__init__() missing 1 required positional argument: 'strategy'
2025-09-09 12:16:25,625: Internal Server Error: /admin/login/
Traceback (most recent call last):
  File "/home/buddyskincare/.virtualenvs/venv/lib/python3.13/site-packages/django/core/handlers/exception.py", line 55, in inner
    response = get_response(request)
  File "/home/buddyskincare/.virtualenvs/venv/lib/python3.13/site-packages/django/core/handlers/base.py", line 197, in _get_response
    response = wrapped_callback(request, *callback_args, **callback_kwargs)
  File "/home/buddyskincare/.virtualenvs/venv/lib/python3.13/site-packages/django/utils/decorators.py", line 48, in _wrapper
    return bound_method(*args, **kwargs)
  File "/home/buddyskincare/.virtualenvs/venv/lib/python3.13/site-packages/django/views/decorators/cache.py", line 80, in _view_wrapper
    response = view_func(request, *args, **kwargs)
  File "/home/buddyskincare/.virtualenvs/venv/lib/python3.13/site-packages/django/contrib/admin/sites.py", line 430, in login
    **self.each_context(request),
      ~~~~~~~~~~~~~~~~~^^^^^^^^^
  File "/home/buddyskincare/.virtualenvs/venv/lib/python3.13/site-packages/django/contrib/admin/sites.py", line 343, in each_context
    "available_apps": self.get_app_list(request),
                      ~~~~~~~~~~~~~~~~~^^^^^^^^^
  File "/home/buddyskincare/.virtualenvs/venv/lib/python3.13/site-packages/django/contrib/admin/sites.py", line 546, in get_app_list
    app_dict = self._build_app_dict(request, app_label)
  File "/home/buddyskincare/.virtualenvs/venv/lib/python3.13/site-packages/django/contrib/admin/sites.py", line 488, in _build_app_dict
    has_module_perms = model_admin.has_module_permission(request)
  File "/home/buddyskincare/.virtualenvs/venv/lib/python3.13/site-packages/django/contrib/admin/options.py", line 641, in has_module_permission
    return request.user.has_module_perms(self.opts.app_label)
           ~~~~~~~~~~~~~~~~~~~~~~~~~~~~~^^^^^^^^^^^^^^^^^^^^^
  File "/home/buddyskincare/.virtualenvs/venv/lib/python3.13/site-packages/django/contrib/auth/models.py", line 620, in has_module_perms
    return _user_has_module_perms(self, module)
  File "/home/buddyskincare/.virtualenvs/venv/lib/python3.13/site-packages/django/contrib/auth/models.py", line 293, in _user_has_module_perms
    for backend in auth.get_backends():
                   ~~~~~~~~~~~~~~~~~^^
  File "/home/buddyskincare/.virtualenvs/venv/lib/python3.13/site-packages/django/contrib/auth/__init__.py", line 40, in get_backends
    return _get_backends(return_tuples=False)
  File "/home/buddyskincare/.virtualenvs/venv/lib/python3.13/site-packages/django/contrib/auth/__init__.py", line 29, in _get_backends
    backend = load_backend(backend_path)
  File "/home/buddyskincare/.virtualenvs/venv/lib/python3.13/site-packages/django/contrib/auth/__init__.py", line 23, in load_backend
    return import_string(path)()
           ~~~~~~~~~~~~~~~~~~~^^
TypeError: BaseAuth.__init__() missing 1 required positional argument: 'strategy'
2025-09-09 12:16:34,130: Internal Server Error: /admin/login/
Traceback (most recent call last):
  File "/home/buddyskincare/.virtualenvs/venv/lib/python3.13/site-packages/django/core/handlers/exception.py", line 55, in inner
    response = get_response(request)
  File "/home/buddyskincare/.virtualenvs/venv/lib/python3.13/site-packages/django/core/handlers/base.py", line 197, in _get_response
    response = wrapped_callback(request, *callback_args, **callback_kwargs)
  File "/home/buddyskincare/.virtualenvs/venv/lib/python3.13/site-packages/django/utils/decorators.py", line 48, in _wrapper
    return bound_method(*args, **kwargs)
  File "/home/buddyskincare/.virtualenvs/venv/lib/python3.13/site-packages/django/views/decorators/cache.py", line 80, in _view_wrapper
    response = view_func(request, *args, **kwargs)
  File "/home/buddyskincare/.virtualenvs/venv/lib/python3.13/site-packages/django/contrib/admin/sites.py", line 430, in login
    **self.each_context(request),
      ~~~~~~~~~~~~~~~~~^^^^^^^^^
  File "/home/buddyskincare/.virtualenvs/venv/lib/python3.13/site-packages/django/contrib/admin/sites.py", line 343, in each_context
    "available_apps": self.get_app_list(request),
                      ~~~~~~~~~~~~~~~~~^^^^^^^^^
  File "/home/buddyskincare/.virtualenvs/venv/lib/python3.13/site-packages/django/contrib/admin/sites.py", line 546, in get_app_list
    app_dict = self._build_app_dict(request, app_label)
  File "/home/buddyskincare/.virtualenvs/venv/lib/python3.13/site-packages/django/contrib/admin/sites.py", line 488, in _build_app_dict
    has_module_perms = model_admin.has_module_permission(request)
  File "/home/buddyskincare/.virtualenvs/venv/lib/python3.13/site-packages/django/contrib/admin/options.py", line 641, in has_module_permission
    return request.user.has_module_perms(self.opts.app_label)
           ~~~~~~~~~~~~~~~~~~~~~~~~~~~~~^^^^^^^^^^^^^^^^^^^^^
  File "/home/buddyskincare/.virtualenvs/venv/lib/python3.13/site-packages/django/contrib/auth/models.py", line 620, in has_module_perms
    return _user_has_module_perms(self, module)
  File "/home/buddyskincare/.virtualenvs/venv/lib/python3.13/site-packages/django/contrib/auth/models.py", line 293, in _user_has_module_perms
    for backend in auth.get_backends():
                   ~~~~~~~~~~~~~~~~~^^
  File "/home/buddyskincare/.virtualenvs/venv/lib/python3.13/site-packages/django/contrib/auth/__init__.py", line 40, in get_backends
    return _get_backends(return_tuples=False)
  File "/home/buddyskincare/.virtualenvs/venv/lib/python3.13/site-packages/django/contrib/auth/__init__.py", line 29, in _get_backends
    backend = load_backend(backend_path)
  File "/home/buddyskincare/.virtualenvs/venv/lib/python3.13/site-packages/django/contrib/auth/__init__.py", line 23, in load_backend
    return import_string(path)()
           ~~~~~~~~~~~~~~~~~~~^^
TypeError: BaseAuth.__init__() missing 1 required positional argument: 'strategy'
2025-09-09 12:18:23,314: Internal Server Error: /admin/login/
Traceback (most recent call last):
  File "/home/buddyskincare/.virtualenvs/venv/lib/python3.13/site-packages/django/utils/module_loading.py", line 30, in import_string
    return cached_import(module_path, class_name)
  File "/home/buddyskincare/.virtualenvs/venv/lib/python3.13/site-packages/django/utils/module_loading.py", line 16, in cached_import
    return getattr(module, class_name)
AttributeError: module 'BuddyApp.backends' has no attribute 'PhoneNumberAuthenticationBackend'
**NO MATCH**
The above exception was the direct cause of the following exception:
**NO MATCH**
Traceback (most recent call last):
  File "/home/buddyskincare/.virtualenvs/venv/lib/python3.13/site-packages/django/core/handlers/exception.py", line 55, in inner
    response = get_response(request)
  File "/home/buddyskincare/.virtualenvs/venv/lib/python3.13/site-packages/django/core/handlers/base.py", line 197, in _get_response
    response = wrapped_callback(request, *callback_args, **callback_kwargs)
  File "/home/buddyskincare/.virtualenvs/venv/lib/python3.13/site-packages/django/utils/decorators.py", line 48, in _wrapper
    return bound_method(*args, **kwargs)
  File "/home/buddyskincare/.virtualenvs/venv/lib/python3.13/site-packages/django/views/decorators/cache.py", line 80, in _view_wrapper
    response = view_func(request, *args, **kwargs)
  File "/home/buddyskincare/.virtualenvs/venv/lib/python3.13/site-packages/django/contrib/admin/sites.py", line 430, in login
    **self.each_context(request),
      ~~~~~~~~~~~~~~~~~^^^^^^^^^
  File "/home/buddyskincare/.virtualenvs/venv/lib/python3.13/site-packages/django/contrib/admin/sites.py", line 343, in each_context
    "available_apps": self.get_app_list(request),
                      ~~~~~~~~~~~~~~~~~^^^^^^^^^
  File "/home/buddyskincare/.virtualenvs/venv/lib/python3.13/site-packages/django/contrib/admin/sites.py", line 546, in get_app_list
    app_dict = self._build_app_dict(request, app_label)
  File "/home/buddyskincare/.virtualenvs/venv/lib/python3.13/site-packages/django/contrib/admin/sites.py", line 488, in _build_app_dict
    has_module_perms = model_admin.has_module_permission(request)
  File "/home/buddyskincare/.virtualenvs/venv/lib/python3.13/site-packages/django/contrib/admin/options.py", line 641, in has_module_permission
    return request.user.has_module_perms(self.opts.app_label)
           ~~~~~~~~~~~~~~~~~~~~~~~~~~~~~^^^^^^^^^^^^^^^^^^^^^
  File "/home/buddyskincare/.virtualenvs/venv/lib/python3.13/site-packages/django/contrib/auth/models.py", line 620, in has_module_perms
    return _user_has_module_perms(self, module)
  File "/home/buddyskincare/.virtualenvs/venv/lib/python3.13/site-packages/django/contrib/auth/models.py", line 293, in _user_has_module_perms
    for backend in auth.get_backends():
                   ~~~~~~~~~~~~~~~~~^^
  File "/home/buddyskincare/.virtualenvs/venv/lib/python3.13/site-packages/django/contrib/auth/__init__.py", line 40, in get_backends
    return _get_backends(return_tuples=False)
  File "/home/buddyskincare/.virtualenvs/venv/lib/python3.13/site-packages/django/contrib/auth/__init__.py", line 29, in _get_backends
    backend = load_backend(backend_path)
  File "/home/buddyskincare/.virtualenvs/venv/lib/python3.13/site-packages/django/contrib/auth/__init__.py", line 23, in load_backend
    return import_string(path)()
           ~~~~~~~~~~~~~^^^^^^
  File "/home/buddyskincare/.virtualenvs/venv/lib/python3.13/site-packages/django/utils/module_loading.py", line 32, in import_string
    raise ImportError(
    ...<2 lines>...
    ) from err
ImportError: Module "BuddyApp.backends" does not define a "PhoneNumberAuthenticationBackend" attribute/class
2025-09-09 13:57:44,541: Internal Server Error: /admin/login/
Traceback (most recent call last):
  File "/home/buddyskincare/.virtualenvs/venv/lib/python3.13/site-packages/django/core/handlers/exception.py", line 55, in inner
    response = get_response(request)
  File "/home/buddyskincare/.virtualenvs/venv/lib/python3.13/site-packages/django/core/handlers/base.py", line 197, in _get_response
    response = wrapped_callback(request, *callback_args, **callback_kwargs)
  File "/home/buddyskincare/.virtualenvs/venv/lib/python3.13/site-packages/django/utils/decorators.py", line 48, in _wrapper
    return bound_method(*args, **kwargs)
  File "/home/buddyskincare/.virtualenvs/venv/lib/python3.13/site-packages/django/views/decorators/cache.py", line 80, in _view_wrapper
    response = view_func(request, *args, **kwargs)
  File "/home/buddyskincare/.virtualenvs/venv/lib/python3.13/site-packages/django/contrib/admin/sites.py", line 430, in login
    **self.each_context(request),
      ~~~~~~~~~~~~~~~~~^^^^^^^^^
  File "/home/buddyskincare/.virtualenvs/venv/lib/python3.13/site-packages/django/contrib/admin/sites.py", line 343, in each_context
    "available_apps": self.get_app_list(request),
                      ~~~~~~~~~~~~~~~~~^^^^^^^^^
  File "/home/buddyskincare/.virtualenvs/venv/lib/python3.13/site-packages/django/contrib/admin/sites.py", line 546, in get_app_list
    app_dict = self._build_app_dict(request, app_label)
  File "/home/buddyskincare/.virtualenvs/venv/lib/python3.13/site-packages/django/contrib/admin/sites.py", line 488, in _build_app_dict
    has_module_perms = model_admin.has_module_permission(request)
  File "/home/buddyskincare/.virtualenvs/venv/lib/python3.13/site-packages/django/contrib/admin/options.py", line 641, in has_module_permission
    return request.user.has_module_perms(self.opts.app_label)
           ~~~~~~~~~~~~~~~~~~~~~~~~~~~~~^^^^^^^^^^^^^^^^^^^^^
  File "/home/buddyskincare/.virtualenvs/venv/lib/python3.13/site-packages/django/contrib/auth/models.py", line 620, in has_module_perms
    return _user_has_module_perms(self, module)
  File "/home/buddyskincare/.virtualenvs/venv/lib/python3.13/site-packages/django/contrib/auth/models.py", line 293, in _user_has_module_perms
    for backend in auth.get_backends():
                   ~~~~~~~~~~~~~~~~~^^
  File "/home/buddyskincare/.virtualenvs/venv/lib/python3.13/site-packages/django/contrib/auth/__init__.py", line 40, in get_backends
    return _get_backends(return_tuples=False)
  File "/home/buddyskincare/.virtualenvs/venv/lib/python3.13/site-packages/django/contrib/auth/__init__.py", line 29, in _get_backends
    backend = load_backend(backend_path)
  File "/home/buddyskincare/.virtualenvs/venv/lib/python3.13/site-packages/django/contrib/auth/__init__.py", line 23, in load_backend
    return import_string(path)()
           ~~~~~~~~~~~~~~~~~~~^^
TypeError: BaseAuth.__init__() missing 1 required positional argument: 'strategy'
2025-09-09 14:01:02,747: Internal Server Error: /admin/login/
Traceback (most recent call last):
  File "/home/buddyskincare/.virtualenvs/venv/lib/python3.13/site-packages/django/core/handlers/exception.py", line 55, in inner
    response = get_response(request)
  File "/home/buddyskincare/.virtualenvs/venv/lib/python3.13/site-packages/django/core/handlers/base.py", line 197, in _get_response
    response = wrapped_callback(request, *callback_args, **callback_kwargs)
  File "/home/buddyskincare/.virtualenvs/venv/lib/python3.13/site-packages/django/utils/decorators.py", line 48, in _wrapper
    return bound_method(*args, **kwargs)
  File "/home/buddyskincare/.virtualenvs/venv/lib/python3.13/site-packages/django/views/decorators/cache.py", line 80, in _view_wrapper
    response = view_func(request, *args, **kwargs)
  File "/home/buddyskincare/.virtualenvs/venv/lib/python3.13/site-packages/django/contrib/admin/sites.py", line 430, in login
    **self.each_context(request),
      ~~~~~~~~~~~~~~~~~^^^^^^^^^
  File "/home/buddyskincare/.virtualenvs/venv/lib/python3.13/site-packages/django/contrib/admin/sites.py", line 343, in each_context
    "available_apps": self.get_app_list(request),
                      ~~~~~~~~~~~~~~~~~^^^^^^^^^
  File "/home/buddyskincare/.virtualenvs/venv/lib/python3.13/site-packages/django/contrib/admin/sites.py", line 546, in get_app_list
    app_dict = self._build_app_dict(request, app_label)
  File "/home/buddyskincare/.virtualenvs/venv/lib/python3.13/site-packages/django/contrib/admin/sites.py", line 488, in _build_app_dict
    has_module_perms = model_admin.has_module_permission(request)
  File "/home/buddyskincare/.virtualenvs/venv/lib/python3.13/site-packages/django/contrib/admin/options.py", line 641, in has_module_permission
    return request.user.has_module_perms(self.opts.app_label)
           ~~~~~~~~~~~~~~~~~~~~~~~~~~~~~^^^^^^^^^^^^^^^^^^^^^
  File "/home/buddyskincare/.virtualenvs/venv/lib/python3.13/site-packages/django/contrib/auth/models.py", line 620, in has_module_perms
    return _user_has_module_perms(self, module)
  File "/home/buddyskincare/.virtualenvs/venv/lib/python3.13/site-packages/django/contrib/auth/models.py", line 293, in _user_has_module_perms
    for backend in auth.get_backends():
                   ~~~~~~~~~~~~~~~~~^^
  File "/home/buddyskincare/.virtualenvs/venv/lib/python3.13/site-packages/django/contrib/auth/__init__.py", line 40, in get_backends
    return _get_backends(return_tuples=False)
  File "/home/buddyskincare/.virtualenvs/venv/lib/python3.13/site-packages/django/contrib/auth/__init__.py", line 29, in _get_backends
    backend = load_backend(backend_path)
  File "/home/buddyskincare/.virtualenvs/venv/lib/python3.13/site-packages/django/contrib/auth/__init__.py", line 23, in load_backend
    return import_string(path)()
           ~~~~~~~~~~~~~~~~~~~^^
TypeError: BaseAuth.__init__() missing 1 required positional argument: 'strategy'
2025-09-09 14:05:22,551: Internal Server Error: /admin/login/
Traceback (most recent call last):
  File "/home/buddyskincare/.virtualenvs/venv/lib/python3.13/site-packages/django/core/handlers/exception.py", line 55, in inner
    response = get_response(request)
  File "/home/buddyskincare/.virtualenvs/venv/lib/python3.13/site-packages/django/core/handlers/base.py", line 197, in _get_response
    response = wrapped_callback(request, *callback_args, **callback_kwargs)
  File "/home/buddyskincare/.virtualenvs/venv/lib/python3.13/site-packages/django/utils/decorators.py", line 48, in _wrapper
    return bound_method(*args, **kwargs)
  File "/home/buddyskincare/.virtualenvs/venv/lib/python3.13/site-packages/django/views/decorators/cache.py", line 80, in _view_wrapper
    response = view_func(request, *args, **kwargs)
  File "/home/buddyskincare/.virtualenvs/venv/lib/python3.13/site-packages/django/contrib/admin/sites.py", line 430, in login
    **self.each_context(request),
      ~~~~~~~~~~~~~~~~~^^^^^^^^^
  File "/home/buddyskincare/.virtualenvs/venv/lib/python3.13/site-packages/django/contrib/admin/sites.py", line 343, in each_context
    "available_apps": self.get_app_list(request),
                      ~~~~~~~~~~~~~~~~~^^^^^^^^^
  File "/home/buddyskincare/.virtualenvs/venv/lib/python3.13/site-packages/django/contrib/admin/sites.py", line 546, in get_app_list
    app_dict = self._build_app_dict(request, app_label)
  File "/home/buddyskincare/.virtualenvs/venv/lib/python3.13/site-packages/django/contrib/admin/sites.py", line 488, in _build_app_dict
    has_module_perms = model_admin.has_module_permission(request)
  File "/home/buddyskincare/.virtualenvs/venv/lib/python3.13/site-packages/django/contrib/admin/options.py", line 641, in has_module_permission
    return request.user.has_module_perms(self.opts.app_label)
           ~~~~~~~~~~~~~~~~~~~~~~~~~~~~~^^^^^^^^^^^^^^^^^^^^^
  File "/home/buddyskincare/.virtualenvs/venv/lib/python3.13/site-packages/django/contrib/auth/models.py", line 620, in has_module_perms
    return _user_has_module_perms(self, module)
  File "/home/buddyskincare/.virtualenvs/venv/lib/python3.13/site-packages/django/contrib/auth/models.py", line 293, in _user_has_module_perms
    for backend in auth.get_backends():
                   ~~~~~~~~~~~~~~~~~^^
  File "/home/buddyskincare/.virtualenvs/venv/lib/python3.13/site-packages/django/contrib/auth/__init__.py", line 40, in get_backends
    return _get_backends(return_tuples=False)
  File "/home/buddyskincare/.virtualenvs/venv/lib/python3.13/site-packages/django/contrib/auth/__init__.py", line 29, in _get_backends
    backend = load_backend(backend_path)
  File "/home/buddyskincare/.virtualenvs/venv/lib/python3.13/site-packages/django/contrib/auth/__init__.py", line 23, in load_backend
    return import_string(path)()
           ~~~~~~~~~~~~~~~~~~~^^
TypeError: BaseAuth.__init__() missing 1 required positional argument: 'strategy'
2025-09-09 14:07:56,658: Internal Server Error: /admin/login/
Traceback (most recent call last):
  File "/home/buddyskincare/.virtualenvs/venv/lib/python3.13/site-packages/django/core/handlers/exception.py", line 55, in inner
    response = get_response(request)
  File "/home/buddyskincare/.virtualenvs/venv/lib/python3.13/site-packages/django/core/handlers/base.py", line 197, in _get_response
    response = wrapped_callback(request, *callback_args, **callback_kwargs)
  File "/home/buddyskincare/.virtualenvs/venv/lib/python3.13/site-packages/django/utils/decorators.py", line 48, in _wrapper
    return bound_method(*args, **kwargs)
  File "/home/buddyskincare/.virtualenvs/venv/lib/python3.13/site-packages/django/views/decorators/cache.py", line 80, in _view_wrapper
    response = view_func(request, *args, **kwargs)
  File "/home/buddyskincare/.virtualenvs/venv/lib/python3.13/site-packages/django/contrib/admin/sites.py", line 430, in login
    **self.each_context(request),
      ~~~~~~~~~~~~~~~~~^^^^^^^^^
  File "/home/buddyskincare/.virtualenvs/venv/lib/python3.13/site-packages/django/contrib/admin/sites.py", line 343, in each_context
    "available_apps": self.get_app_list(request),
                      ~~~~~~~~~~~~~~~~~^^^^^^^^^
  File "/home/buddyskincare/.virtualenvs/venv/lib/python3.13/site-packages/django/contrib/admin/sites.py", line 546, in get_app_list
    app_dict = self._build_app_dict(request, app_label)
  File "/home/buddyskincare/.virtualenvs/venv/lib/python3.13/site-packages/django/contrib/admin/sites.py", line 488, in _build_app_dict
    has_module_perms = model_admin.has_module_permission(request)
  File "/home/buddyskincare/.virtualenvs/venv/lib/python3.13/site-packages/django/contrib/admin/options.py", line 641, in has_module_permission
    return request.user.has_module_perms(self.opts.app_label)
           ~~~~~~~~~~~~~~~~~~~~~~~~~~~~~^^^^^^^^^^^^^^^^^^^^^
  File "/home/buddyskincare/.virtualenvs/venv/lib/python3.13/site-packages/django/contrib/auth/models.py", line 620, in has_module_perms
    return _user_has_module_perms(self, module)
  File "/home/buddyskincare/.virtualenvs/venv/lib/python3.13/site-packages/django/contrib/auth/models.py", line 293, in _user_has_module_perms
    for backend in auth.get_backends():
                   ~~~~~~~~~~~~~~~~~^^
  File "/home/buddyskincare/.virtualenvs/venv/lib/python3.13/site-packages/django/contrib/auth/__init__.py", line 40, in get_backends
    return _get_backends(return_tuples=False)
  File "/home/buddyskincare/.virtualenvs/venv/lib/python3.13/site-packages/django/contrib/auth/__init__.py", line 29, in _get_backends
    backend = load_backend(backend_path)
  File "/home/buddyskincare/.virtualenvs/venv/lib/python3.13/site-packages/django/contrib/auth/__init__.py", line 23, in load_backend
    return import_string(path)()
           ~~~~~~~~~~~~~~~~~~~^^
TypeError: BaseAuth.__init__() missing 1 required positional argument: 'strategy'
2025-09-09 14:07:57,811: Internal Server Error: /admin/login/
Traceback (most recent call last):
  File "/home/buddyskincare/.virtualenvs/venv/lib/python3.13/site-packages/django/core/handlers/exception.py", line 55, in inner
    response = get_response(request)
  File "/home/buddyskincare/.virtualenvs/venv/lib/python3.13/site-packages/django/core/handlers/base.py", line 197, in _get_response
    response = wrapped_callback(request, *callback_args, **callback_kwargs)
  File "/home/buddyskincare/.virtualenvs/venv/lib/python3.13/site-packages/django/utils/decorators.py", line 48, in _wrapper
    return bound_method(*args, **kwargs)
  File "/home/buddyskincare/.virtualenvs/venv/lib/python3.13/site-packages/django/views/decorators/cache.py", line 80, in _view_wrapper
    response = view_func(request, *args, **kwargs)
  File "/home/buddyskincare/.virtualenvs/venv/lib/python3.13/site-packages/django/contrib/admin/sites.py", line 430, in login
    **self.each_context(request),
      ~~~~~~~~~~~~~~~~~^^^^^^^^^
  File "/home/buddyskincare/.virtualenvs/venv/lib/python3.13/site-packages/django/contrib/admin/sites.py", line 343, in each_context
    "available_apps": self.get_app_list(request),
                      ~~~~~~~~~~~~~~~~~^^^^^^^^^
  File "/home/buddyskincare/.virtualenvs/venv/lib/python3.13/site-packages/django/contrib/admin/sites.py", line 546, in get_app_list
    app_dict = self._build_app_dict(request, app_label)
  File "/home/buddyskincare/.virtualenvs/venv/lib/python3.13/site-packages/django/contrib/admin/sites.py", line 488, in _build_app_dict
    has_module_perms = model_admin.has_module_permission(request)
  File "/home/buddyskincare/.virtualenvs/venv/lib/python3.13/site-packages/django/contrib/admin/options.py", line 641, in has_module_permission
    return request.user.has_module_perms(self.opts.app_label)
           ~~~~~~~~~~~~~~~~~~~~~~~~~~~~~^^^^^^^^^^^^^^^^^^^^^
  File "/home/buddyskincare/.virtualenvs/venv/lib/python3.13/site-packages/django/contrib/auth/models.py", line 620, in has_module_perms
    return _user_has_module_perms(self, module)
  File "/home/buddyskincare/.virtualenvs/venv/lib/python3.13/site-packages/django/contrib/auth/models.py", line 293, in _user_has_module_perms
    for backend in auth.get_backends():
                   ~~~~~~~~~~~~~~~~~^^
  File "/home/buddyskincare/.virtualenvs/venv/lib/python3.13/site-packages/django/contrib/auth/__init__.py", line 40, in get_backends
    return _get_backends(return_tuples=False)
  File "/home/buddyskincare/.virtualenvs/venv/lib/python3.13/site-packages/django/contrib/auth/__init__.py", line 29, in _get_backends
    backend = load_backend(backend_path)
  File "/home/buddyskincare/.virtualenvs/venv/lib/python3.13/site-packages/django/contrib/auth/__init__.py", line 23, in load_backend
    return import_string(path)()
           ~~~~~~~~~~~~~~~~~~~^^
TypeError: BaseAuth.__init__() missing 1 required positional argument: 'strategy'
2025-09-09 14:07:59,915: Internal Server Error: /admin/login/
Traceback (most recent call last):
  File "/home/buddyskincare/.virtualenvs/venv/lib/python3.13/site-packages/django/core/handlers/exception.py", line 55, in inner
    response = get_response(request)
  File "/home/buddyskincare/.virtualenvs/venv/lib/python3.13/site-packages/django/core/handlers/base.py", line 197, in _get_response
    response = wrapped_callback(request, *callback_args, **callback_kwargs)
  File "/home/buddyskincare/.virtualenvs/venv/lib/python3.13/site-packages/django/utils/decorators.py", line 48, in _wrapper
    return bound_method(*args, **kwargs)
  File "/home/buddyskincare/.virtualenvs/venv/lib/python3.13/site-packages/django/views/decorators/cache.py", line 80, in _view_wrapper
    response = view_func(request, *args, **kwargs)
  File "/home/buddyskincare/.virtualenvs/venv/lib/python3.13/site-packages/django/contrib/admin/sites.py", line 430, in login
    **self.each_context(request),
      ~~~~~~~~~~~~~~~~~^^^^^^^^^
  File "/home/buddyskincare/.virtualenvs/venv/lib/python3.13/site-packages/django/contrib/admin/sites.py", line 343, in each_context
    "available_apps": self.get_app_list(request),
                      ~~~~~~~~~~~~~~~~~^^^^^^^^^
  File "/home/buddyskincare/.virtualenvs/venv/lib/python3.13/site-packages/django/contrib/admin/sites.py", line 546, in get_app_list
    app_dict = self._build_app_dict(request, app_label)
  File "/home/buddyskincare/.virtualenvs/venv/lib/python3.13/site-packages/django/contrib/admin/sites.py", line 488, in _build_app_dict
    has_module_perms = model_admin.has_module_permission(request)
  File "/home/buddyskincare/.virtualenvs/venv/lib/python3.13/site-packages/django/contrib/admin/options.py", line 641, in has_module_permission
    return request.user.has_module_perms(self.opts.app_label)
           ~~~~~~~~~~~~~~~~~~~~~~~~~~~~~^^^^^^^^^^^^^^^^^^^^^
  File "/home/buddyskincare/.virtualenvs/venv/lib/python3.13/site-packages/django/contrib/auth/models.py", line 620, in has_module_perms
    return _user_has_module_perms(self, module)
  File "/home/buddyskincare/.virtualenvs/venv/lib/python3.13/site-packages/django/contrib/auth/models.py", line 293, in _user_has_module_perms
    for backend in auth.get_backends():
                   ~~~~~~~~~~~~~~~~~^^
  File "/home/buddyskincare/.virtualenvs/venv/lib/python3.13/site-packages/django/contrib/auth/__init__.py", line 40, in get_backends
    return _get_backends(return_tuples=False)
  File "/home/buddyskincare/.virtualenvs/venv/lib/python3.13/site-packages/django/contrib/auth/__init__.py", line 29, in _get_backends
    backend = load_backend(backend_path)
  File "/home/buddyskincare/.virtualenvs/venv/lib/python3.13/site-packages/django/contrib/auth/__init__.py", line 23, in load_backend
    return import_string(path)()
           ~~~~~~~~~~~~~~~~~~~^^
TypeError: BaseAuth.__init__() missing 1 required positional argument: 'strategy'
2025-09-09 14:11:30,567: Internal Server Error: /admin/login/
Traceback (most recent call last):
  File "/home/buddyskincare/.virtualenvs/venv/lib/python3.13/site-packages/django/core/handlers/exception.py", line 55, in inner
    response = get_response(request)
  File "/home/buddyskincare/.virtualenvs/venv/lib/python3.13/site-packages/django/core/handlers/base.py", line 197, in _get_response
    response = wrapped_callback(request, *callback_args, **callback_kwargs)
  File "/home/buddyskincare/.virtualenvs/venv/lib/python3.13/site-packages/django/utils/decorators.py", line 48, in _wrapper
    return bound_method(*args, **kwargs)
  File "/home/buddyskincare/.virtualenvs/venv/lib/python3.13/site-packages/django/views/decorators/cache.py", line 80, in _view_wrapper
    response = view_func(request, *args, **kwargs)
  File "/home/buddyskincare/.virtualenvs/venv/lib/python3.13/site-packages/django/contrib/admin/sites.py", line 430, in login
    **self.each_context(request),
      ~~~~~~~~~~~~~~~~~^^^^^^^^^
  File "/home/buddyskincare/.virtualenvs/venv/lib/python3.13/site-packages/django/contrib/admin/sites.py", line 343, in each_context
    "available_apps": self.get_app_list(request),
                      ~~~~~~~~~~~~~~~~~^^^^^^^^^
  File "/home/buddyskincare/.virtualenvs/venv/lib/python3.13/site-packages/django/contrib/admin/sites.py", line 546, in get_app_list
    app_dict = self._build_app_dict(request, app_label)
  File "/home/buddyskincare/.virtualenvs/venv/lib/python3.13/site-packages/django/contrib/admin/sites.py", line 488, in _build_app_dict
    has_module_perms = model_admin.has_module_permission(request)
  File "/home/buddyskincare/.virtualenvs/venv/lib/python3.13/site-packages/django/contrib/admin/options.py", line 641, in has_module_permission
    return request.user.has_module_perms(self.opts.app_label)
           ~~~~~~~~~~~~~~~~~~~~~~~~~~~~~^^^^^^^^^^^^^^^^^^^^^
  File "/home/buddyskincare/.virtualenvs/venv/lib/python3.13/site-packages/django/contrib/auth/models.py", line 620, in has_module_perms
    return _user_has_module_perms(self, module)
  File "/home/buddyskincare/.virtualenvs/venv/lib/python3.13/site-packages/django/contrib/auth/models.py", line 293, in _user_has_module_perms
    for backend in auth.get_backends():
                   ~~~~~~~~~~~~~~~~~^^
  File "/home/buddyskincare/.virtualenvs/venv/lib/python3.13/site-packages/django/contrib/auth/__init__.py", line 40, in get_backends
    return _get_backends(return_tuples=False)
TypeError: BaseAuth.__init__() missing 1 required positional argument: 'strategy'
2025-09-09 14:18:55,276: Internal Server Error: /admin/login/
Traceback (most recent call last):
  File "/home/buddyskincare/.virtualenvs/venv/lib/python3.13/site-packages/django/core/handlers/exception.py", line 55, in inner
    response = get_response(request)
  File "/home/buddyskincare/.virtualenvs/venv/lib/python3.13/site-packages/django/core/handlers/base.py", line 197, in _get_response
    response = wrapped_callback(request, *callback_args, **callback_kwargs)
  File "/home/buddyskincare/.virtualenvs/venv/lib/python3.13/site-packages/django/utils/decorators.py", line 48, in _wrapper
    return bound_method(*args, **kwargs)
  File "/home/buddyskincare/.virtualenvs/venv/lib/python3.13/site-packages/django/views/decorators/cache.py", line 80, in _view_wrapper
    response = view_func(request, *args, **kwargs)
  File "/home/buddyskincare/.virtualenvs/venv/lib/python3.13/site-packages/django/contrib/admin/sites.py", line 430, in login
    **self.each_context(request),
      ~~~~~~~~~~~~~~~~~^^^^^^^^^
  File "/home/buddyskincare/.virtualenvs/venv/lib/python3.13/site-packages/django/contrib/admin/sites.py", line 343, in each_context
    "available_apps": self.get_app_list(request),
                      ~~~~~~~~~~~~~~~~~^^^^^^^^^
  File "/home/buddyskincare/.virtualenvs/venv/lib/python3.13/site-packages/django/contrib/admin/sites.py", line 546, in get_app_list
    app_dict = self._build_app_dict(request, app_label)
  File "/home/buddyskincare/.virtualenvs/venv/lib/python3.13/site-packages/django/contrib/admin/sites.py", line 488, in _build_app_dict
    has_module_perms = model_admin.has_module_permission(request)
  File "/home/buddyskincare/.virtualenvs/venv/lib/python3.13/site-packages/django/contrib/admin/options.py", line 641, in has_module_permission
    return request.user.has_module_perms(self.opts.app_label)
           ~~~~~~~~~~~~~~~~~~~~~~~~~~~~~^^^^^^^^^^^^^^^^^^^^^
  File "/home/buddyskincare/.virtualenvs/venv/lib/python3.13/site-packages/django/contrib/auth/models.py", line 620, in has_module_perms
    return _user_has_module_perms(self, module)
  File "/home/buddyskincare/.virtualenvs/venv/lib/python3.13/site-packages/django/contrib/auth/models.py", line 293, in _user_has_module_perms
    for backend in auth.get_backends():
                   ~~~~~~~~~~~~~~~~~^^
  File "/home/buddyskincare/.virtualenvs/venv/lib/python3.13/site-packages/django/contrib/auth/__init__.py", line 40, in get_backends
    return _get_backends(return_tuples=False)
  File "/home/buddyskincare/.virtualenvs/venv/lib/python3.13/site-packages/django/contrib/auth/__init__.py", line 29, in _get_backends
    backend = load_backend(backend_path)
  File "/home/buddyskincare/.virtualenvs/venv/lib/python3.13/site-packages/django/contrib/auth/__init__.py", line 23, in load_backend
    return import_string(path)()
           ~~~~~~~~~~~~~~~~~~~^^
TypeError: BaseAuth.__init__() missing 1 required positional argument: 'strategy'
2025-09-09 14:23:35,605: Internal Server Error: /admin/login/
Traceback (most recent call last):
  File "/home/buddyskincare/.virtualenvs/venv/lib/python3.13/site-packages/django/core/handlers/exception.py", line 55, in inner
    response = get_response(request)
  File "/home/buddyskincare/.virtualenvs/venv/lib/python3.13/site-packages/django/core/handlers/base.py", line 197, in _get_response
    response = wrapped_callback(request, *callback_args, **callback_kwargs)
  File "/home/buddyskincare/.virtualenvs/venv/lib/python3.13/site-packages/django/utils/decorators.py", line 48, in _wrapper
    return bound_method(*args, **kwargs)
  File "/home/buddyskincare/.virtualenvs/venv/lib/python3.13/site-packages/django/views/decorators/cache.py", line 80, in _view_wrapper
    response = view_func(request, *args, **kwargs)
  File "/home/buddyskincare/.virtualenvs/venv/lib/python3.13/site-packages/django/contrib/admin/sites.py", line 430, in login
    **self.each_context(request),
      ~~~~~~~~~~~~~~~~~^^^^^^^^^
  File "/home/buddyskincare/.virtualenvs/venv/lib/python3.13/site-packages/django/contrib/admin/sites.py", line 343, in each_context
    "available_apps": self.get_app_list(request),
                      ~~~~~~~~~~~~~~~~~^^^^^^^^^
  File "/home/buddyskincare/.virtualenvs/venv/lib/python3.13/site-packages/django/contrib/admin/sites.py", line 546, in get_app_list
    app_dict = self._build_app_dict(request, app_label)
  File "/home/buddyskincare/.virtualenvs/venv/lib/python3.13/site-packages/django/contrib/admin/sites.py", line 488, in _build_app_dict
    has_module_perms = model_admin.has_module_permission(request)
  File "/home/buddyskincare/.virtualenvs/venv/lib/python3.13/site-packages/django/contrib/admin/options.py", line 641, in has_module_permission
    return request.user.has_module_perms(self.opts.app_label)
           ~~~~~~~~~~~~~~~~~~~~~~~~~~~~~^^^^^^^^^^^^^^^^^^^^^
  File "/home/buddyskincare/.virtualenvs/venv/lib/python3.13/site-packages/django/contrib/auth/models.py", line 620, in has_module_perms
    return _user_has_module_perms(self, module)
  File "/home/buddyskincare/.virtualenvs/venv/lib/python3.13/site-packages/django/contrib/auth/models.py", line 293, in _user_has_module_perms
    for backend in auth.get_backends():
                   ~~~~~~~~~~~~~~~~~^^
  File "/home/buddyskincare/.virtualenvs/venv/lib/python3.13/site-packages/django/contrib/auth/__init__.py", line 40, in get_backends
    return _get_backends(return_tuples=False)
  File "/home/buddyskincare/.virtualenvs/venv/lib/python3.13/site-packages/django/contrib/auth/__init__.py", line 29, in _get_backends
    backend = load_backend(backend_path)
  File "/home/buddyskincare/.virtualenvs/venv/lib/python3.13/site-packages/django/contrib/auth/__init__.py", line 23, in load_backend
    return import_string(path)()
           ~~~~~~~~~~~~~~~~~~~^^
TypeError: BaseAuth.__init__() missing 1 required positional argument: 'strategy'
2025-09-09 14:26:04,719: Internal Server Error: /admin/login/
Traceback (most recent call last):
  File "/home/buddyskincare/.virtualenvs/venv/lib/python3.13/site-packages/django/utils/module_loading.py", line 30, in import_string
    return cached_import(module_path, class_name)
  File "/home/buddyskincare/.virtualenvs/venv/lib/python3.13/site-packages/django/utils/module_loading.py", line 16, in cached_import
    return getattr(module, class_name)
AttributeError: module 'BuddyApp.backends' has no attribute 'PhoneNumberAuthenticationBackend'
**NO MATCH**
The above exception was the direct cause of the following exception:
**NO MATCH**
Traceback (most recent call last):
  File "/home/buddyskincare/.virtualenvs/venv/lib/python3.13/site-packages/django/core/handlers/exception.py", line 55, in inner
    response = get_response(request)
  File "/home/buddyskincare/.virtualenvs/venv/lib/python3.13/site-packages/django/core/handlers/base.py", line 197, in _get_response
    response = wrapped_callback(request, *callback_args, **callback_kwargs)
  File "/home/buddyskincare/.virtualenvs/venv/lib/python3.13/site-packages/django/utils/decorators.py", line 48, in _wrapper
    return bound_method(*args, **kwargs)
  File "/home/buddyskincare/.virtualenvs/venv/lib/python3.13/site-packages/django/views/decorators/cache.py", line 80, in _view_wrapper
    response = view_func(request, *args, **kwargs)
  File "/home/buddyskincare/.virtualenvs/venv/lib/python3.13/site-packages/django/contrib/admin/sites.py", line 430, in login
    **self.each_context(request),
      ~~~~~~~~~~~~~~~~~^^^^^^^^^
  File "/home/buddyskincare/.virtualenvs/venv/lib/python3.13/site-packages/django/contrib/admin/sites.py", line 343, in each_context
    "available_apps": self.get_app_list(request),
                      ~~~~~~~~~~~~~~~~~^^^^^^^^^
  File "/home/buddyskincare/.virtualenvs/venv/lib/python3.13/site-packages/django/contrib/admin/sites.py", line 546, in get_app_list
    app_dict = self._build_app_dict(request, app_label)
  File "/home/buddyskincare/.virtualenvs/venv/lib/python3.13/site-packages/django/contrib/admin/sites.py", line 488, in _build_app_dict
    has_module_perms = model_admin.has_module_permission(request)
  File "/home/buddyskincare/.virtualenvs/venv/lib/python3.13/site-packages/django/contrib/admin/options.py", line 641, in has_module_permission
    return request.user.has_module_perms(self.opts.app_label)
           ~~~~~~~~~~~~~~~~~~~~~~~~~~~~~^^^^^^^^^^^^^^^^^^^^^
  File "/home/buddyskincare/.virtualenvs/venv/lib/python3.13/site-packages/django/contrib/auth/models.py", line 620, in has_module_perms
    return _user_has_module_perms(self, module)
  File "/home/buddyskincare/.virtualenvs/venv/lib/python3.13/site-packages/django/contrib/auth/models.py", line 293, in _user_has_module_perms
    for backend in auth.get_backends():
                   ~~~~~~~~~~~~~~~~~^^
  File "/home/buddyskincare/.virtualenvs/venv/lib/python3.13/site-packages/django/contrib/auth/__init__.py", line 40, in get_backends
    return _get_backends(return_tuples=False)
  File "/home/buddyskincare/.virtualenvs/venv/lib/python3.13/site-packages/django/contrib/auth/__init__.py", line 29, in _get_backends
    backend = load_backend(backend_path)
  File "/home/buddyskincare/.virtualenvs/venv/lib/python3.13/site-packages/django/contrib/auth/__init__.py", line 23, in load_backend
    return import_string(path)()
           ~~~~~~~~~~~~~^^^^^^
  File "/home/buddyskincare/.virtualenvs/venv/lib/python3.13/site-packages/django/utils/module_loading.py", line 32, in import_string
    raise ImportError(
    ...<2 lines>...
    ) from err
ImportError: Module "BuddyApp.backends" does not define a "PhoneNumberAuthenticationBackend" attribute/class
2025-09-09 14:26:08,997: Internal Server Error: /admin/login/
Traceback (most recent call last):
  File "/home/buddyskincare/.virtualenvs/venv/lib/python3.13/site-packages/django/utils/module_loading.py", line 30, in import_string
    return cached_import(module_path, class_name)
  File "/home/buddyskincare/.virtualenvs/venv/lib/python3.13/site-packages/django/utils/module_loading.py", line 16, in cached_import
    return getattr(module, class_name)
AttributeError: module 'BuddyApp.backends' has no attribute 'PhoneNumberAuthenticationBackend'
**NO MATCH**
The above exception was the direct cause of the following exception:
**NO MATCH**
Traceback (most recent call last):
  File "/home/buddyskincare/.virtualenvs/venv/lib/python3.13/site-packages/django/core/handlers/exception.py", line 55, in inner
    response = get_response(request)
  File "/home/buddyskincare/.virtualenvs/venv/lib/python3.13/site-packages/django/core/handlers/base.py", line 197, in _get_response
    response = wrapped_callback(request, *callback_args, **callback_kwargs)
  File "/home/buddyskincare/.virtualenvs/venv/lib/python3.13/site-packages/django/utils/decorators.py", line 48, in _wrapper
    return bound_method(*args, **kwargs)
  File "/home/buddyskincare/.virtualenvs/venv/lib/python3.13/site-packages/django/views/decorators/cache.py", line 80, in _view_wrapper
    response = view_func(request, *args, **kwargs)
  File "/home/buddyskincare/.virtualenvs/venv/lib/python3.13/site-packages/django/contrib/admin/sites.py", line 430, in login
    **self.each_context(request),
      ~~~~~~~~~~~~~~~~~^^^^^^^^^
  File "/home/buddyskincare/.virtualenvs/venv/lib/python3.13/site-packages/django/contrib/admin/sites.py", line 343, in each_context
    "available_apps": self.get_app_list(request),
                      ~~~~~~~~~~~~~~~~~^^^^^^^^^
  File "/home/buddyskincare/.virtualenvs/venv/lib/python3.13/site-packages/django/contrib/admin/sites.py", line 546, in get_app_list
    app_dict = self._build_app_dict(request, app_label)
  File "/home/buddyskincare/.virtualenvs/venv/lib/python3.13/site-packages/django/contrib/admin/sites.py", line 488, in _build_app_dict
    has_module_perms = model_admin.has_module_permission(request)
  File "/home/buddyskincare/.virtualenvs/venv/lib/python3.13/site-packages/django/contrib/admin/options.py", line 641, in has_module_permission
    return request.user.has_module_perms(self.opts.app_label)
           ~~~~~~~~~~~~~~~~~~~~~~~~~~~~~^^^^^^^^^^^^^^^^^^^^^
  File "/home/buddyskincare/.virtualenvs/venv/lib/python3.13/site-packages/django/contrib/auth/models.py", line 620, in has_module_perms
    return _user_has_module_perms(self, module)
  File "/home/buddyskincare/.virtualenvs/venv/lib/python3.13/site-packages/django/contrib/auth/models.py", line 293, in _user_has_module_perms
    for backend in auth.get_backends():
                   ~~~~~~~~~~~~~~~~~^^
  File "/home/buddyskincare/.virtualenvs/venv/lib/python3.13/site-packages/django/contrib/auth/__init__.py", line 40, in get_backends
    return _get_backends(return_tuples=False)
  File "/home/buddyskincare/.virtualenvs/venv/lib/python3.13/site-packages/django/contrib/auth/__init__.py", line 29, in _get_backends
    backend = load_backend(backend_path)
  File "/home/buddyskincare/.virtualenvs/venv/lib/python3.13/site-packages/django/contrib/auth/__init__.py", line 23, in load_backend
    return import_string(path)()
           ~~~~~~~~~~~~~^^^^^^
  File "/home/buddyskincare/.virtualenvs/venv/lib/python3.13/site-packages/django/utils/module_loading.py", line 32, in import_string
    raise ImportError(
    ...<2 lines>...
    ) from err
ImportError: Module "BuddyApp.backends" does not define a "PhoneNumberAuthenticationBackend" attribute/class